Workbook

Sheet Dashboard
A1: Institutional Self-Storage Acquisition Dashboard
A3: Key Investment Metrics
A4: Purchase Price | B4: =Inputs!B4 -> 4250000
A5: Total Project Cost | B5: ='Debt & Refi'!B4 -> 4612500
A6: Equity Required | B6: ='Debt & Refi'!B6 -> 4612500
A7: Year 1 NOI | B7: ='Operating Expenses'!B17 -> 526093.66
A8: Year 5 NOI | B8: ='Operating Expenses'!F17 -> 1190879.8
A9: Levered IRR | B9: ='Returns Summary'!B16 -> 0.40394317
A10: Equity Multiple | B10: ='Returns Summary'!B17 -> 4.5405442
A11: Avg Cash-on-Cash | B11: ='Returns Summary'!B18 -> 0.21011815
A12: Year 1 DSCR | B12: ='Returns Summary'!B19 -> N/A
A13: Year 1 Debt Yield | B13: ='Returns Summary'!B20 -> N/A
A14: Exit Value | B14: ='Returns Summary'!B15 -> 16425929
A17: Flags / Credit Committee Checks
A18: DSCR Status | B18: =IF(ISNUMBER(B12),IF(B12>=Inputs!B29,"PASS","FAIL"),"N/A - Unlevered") -> N/A - Unlevered
A19: Debt Yield Status | B19: =IF(ISNUMBER(B13),IF(B13>=8%,"PASS","WATCH"),"N/A - Unlevered") -> N/A - Unlevered
A20: Exit Cap Spread | B20: =Inputs!B34-Inputs!B26 -> 29.55
A21: Stabilized Occ. | B21: =Inputs!B14 -> 0.9
A23: Unlevered Scenario Metrics
A24: Unlevered IRR | B24: ='Returns Summary'!B23 -> 0.14687227
A25: Unlevered Equity Multiple | B25: ='Returns Summary'!B24 -> 1.8700096
A26: Unlevered Avg Cash-on-Cash | B26: ='Returns Summary'!B25 -> 0.08007639
A27: Unlevered Exit Value | B27: ='Returns Summary'!B26 -> 15534422
A28: Unlevered Y5 NOI Yield on Cost | B28: ='Returns Summary'!B28 -> 0.10575076
A30: Expanded Investor Metrics
A31: LP Equity Multiple | B31: ='Returns Summary'!B32 -> 3.8484354
A32: GP Equity Multiple | B32: ='Returns Summary'!B33 -> N/A
A33: MOIC | B33: ='Returns Summary'!B34 -> 4.5405442
A34: Yield on Cost | B34: ='Returns Summary'!B35 -> 0.25818533
A35: Exit Yield | B35: ='Returns Summary'!B36 -> 0.0725
A37: Acquisition Diagnostics
A38: Price per Rentable SF | B38: ='Returns Summary'!B39 -> 89.005236
A39: Price per Unit | B39: ='Returns Summary'!B40 -> 8415.8416
A40: Stabilized Cap | B40: ='Returns Summary'!B42 -> 0.28020702
A41: Going-In Cap | B41: ='Returns Summary'!B41 -> 0.12378674
A42: Debt Mode | B42: ='Returns Summary'!B46 -> Levered
A43: Unlevered Toggle | B43: Yes

Sheet Sources & Notes
A1: Sources & Notes / Model Guide
A3: Purpose | B3: Institutional self-storage acquisition model for lender and investor review.
A4: Replace inputs | B4: All blue/yellow cells are sample inputs and should be replaced with real rent roll, T-12, tax, insurance, debt, construction, and market comp data.
A5: Color convention | B5: Blue/yellow = editable input; green = linked from another worksheet; black = formula.
A6: Caution | B6: Waterfall is an annual simplified promote model and should be reviewed by counsel/CPA before investor use.
A9: Due Diligence Checklist
A10: Rent roll by unit type
A11: T-12 / T-3 P&L
A12: Physical and economic occupancy
A13: Rate history and street rates
A14: Delinquency / bad debt
A15: Tax bill and reassessment
A16: Insurance quote
A17: Debt term sheet
A18: Expansion zoning / permits
A19: Market comp survey URLs

Sheet Inputs
A1: Global Inputs
A3: Acquisition / Fees
A4: Purchase Price | B4: 4250000
A5: Closing Costs % | B5: 0.03
A6: Initial Repairs / Deferred CapEx | B6: 150000
A7: Acquisition Fee % | B7: 0.02
A8: Asset Management Fee % of EGI | B8: 0.015
A9: Disposition Fee % | B9: 0.01
A10: Sponsor Co-Invest % of Equity | B10: 0
A12: Operations
A13: Start Physical Occupancy | B13: 0.707
A14: Stabilized Physical Occupancy | B14: 0.9
A15: Months to Stabilization | B15: 18
A16: Occupancy Curve Type | B16: Logistic
A17: Economic Occupancy Discount | B17: 0.03
A18: Annual Street Rent Growth | B18: 0.05
A19: Admin / Fees % of Rental Revenue | B19: 0.04
A20: Tenant Insurance Income % | B20: 0.05
A21: Other Income / Month | B21: 2500
A22: OpEx Growth | B22: 0.025
A25: Debt / Refi / Exit
A26: Initial LTV | B26: 0.45
A27: Initial Interest Rate | B27: 0.085
A28: Initial Amortization Years | B28: 30
A29: IO Period Months | B29: 24
A30: Minimum DSCR | B30: 1.25
A31: Refi Month | B31: 24
A32: Refi LTV | B32: 0.65
A33: Refi Interest Rate | B33: 0.0525
A34: Refi Amortization Years | B34: 30
A35: Exit Cap Rate | B35: 0.0725
A36: Exit Month | B36: 60
A37: Selling Costs % | B37: 0.02
... A46: Residual Split - GP | B46: 0.2
A48: Debt Toggle / Structure
A49: Unlevered? (Yes/No) | B49: No
A50: Active Capital Structure | B50: =IF($B$49="Yes","Unlevered","Levered") -> Levered
A51: LP Contributes 100% Equity? | B51: Yes
A52: Notes | B52: Set Unlevered? to No to activate LTV-based debt sizing and debt service.

Sheet Unit Mix & Market Comps
A1: Unit Mix & Market Rent Comp Integration
A3: Subject Unit Mix
A4: Unit Type | B4: Units | C4: Avg SF | D4: Current Rent / Mo. | E4: Market Rent / Mo. | F4: Premium / Discount | G4: Current Annual GPR | H4: Market Annual GPR
A5: 5x5 | B5: 100 | C5: 25 | D5: 80 | E5: 90 | F5: =IFERROR(E5/D5-1,0) -> 0.125 | G5: =B5*D5*12 -> 96000 | H5: =B5*E5*12 -> 108000
A6: 5x10 | B6: 120 | C6: 50 | D6: 125 | E6: 135 | F6: =IFERROR(E6/D6-1,0) -> 0.08 | G6: =B6*D6*12 -> 180000 | H6: =B6*E6*12 -> 194400
A7: 10x10 | B7: 140 | C7: 100 | D7: 205 | E7: 225 | F7: =IFERROR(E7/D7-1,0) -> 0.097560976 | G7: =B7*D7*12 -> 344400 | H7: =B7*E7*12 -> 378000
A8: 10x15 | B8: 75 | C8: 150 | D8: 285 | E8: 310 | F8: =IFERROR(E8/D8-1,0) -> 0.087719298 | G8: =B8*D8*12 -> 256500 | H8: =B8*E8*12 -> 279000
A9: 10x20 | B9: 50 | C9: 200 | D9: 375 | E9: 410 | F9: =IFERROR(E9/D9-1,0) -> 0.093333333 | G9: =B9*D9*12 -> 225000 | H9: =B9*E9*12 -> 246000
A10: Parking / Outdoor | B10: 20 | C10: 200 | D10: 150 | E10: 175 | F10: =IFERROR(E10/D10-1,0) -> 0.16666667 | G10: =B10*D10*12 -> 36000 | H10: =B10*E10*12 -> 42000
A11: Total / Weighted Avg | B11: =SUM(B5:B10) -> 505 | C11: =SUMPRODUCT(B5:B10,C5:C10)/B11 -> 94.554455 | D11: =SUMPRODUCT(B5:B10,D5:D10)/B11 -> 187.77228 | E11: =SUMPRODUCT(B5:B10,E5:E10)/B11 -> 205.84158 | F11: =IFERROR(E11/D11-1,0) -> 0.096229897 | G11: =SUM(G5:G10) -> 1137900 | H11: =SUM(H5:H10) -> 1247400
A14: Market Rent Comps
A15: Comp Name | B15: Market / Address | C15: Distance | D15: Unit Type | E15: Quoted Rent / Mo. | F15: Source / URL | G15: Date | H15: Notes
A16: Comp 1 | D16: 10x10 | E16: 0 | F16: Add source URL
A17: Comp 2 | D17: 10x10 | E17: 0 | F17: Add source URL
A18: Comp 3 | D18: 10x10 | E18: 0 | F18: Add source URL
A19: Comp 4 | D19: 10x10 | E19: 0 | F19: Add source URL
A20: Comp 5 | D20: 10x10 | E20: 0 | F20: Add source URL
A21: Comp 6 | D21: 10x10 | E21: 0 | F21: Add source URL
A22: Comp 7 | D22: 10x10 | E22: 0 | F22: Add source URL
A23: Comp 8 | D23: 10x10 | E23: 0 | F23: Add source URL
A24: Comp 9 | D24: 10x10 | E24: 0 | F24: Add source URL
A25: Comp 10 | D25: 10x10 | E25: 0 | F25: Add source URL
A28: Comp Summary
A29: Average Quoted Rent / Mo. | B29: =IFERROR(AVERAGEIF(E16:E25,">0",E16:E25),"N/A") -> N/A
A30: Subject Weighted Market Rent / Mo. | B30: =E11 -> 205.84158
A31: Subject vs Comp Rent | B31: =IFERROR(B30/B29-1,0) -> 0

Sheet Monthly Lease-Up
A1: Monthly Lease-Up / Dynamic Occupancy Curves
A3: Month | B3: Year | C3: Beginning Occ. | D3: Curve Occ. | E3: Physical Occ. | F3: Leased Units | G3: Economic Occ. | H3: Monthly Rent Growth | I3: Weighted Market Rent | J3: Rental Revenue | K3: Ancillary Income | L3: Total EGI
A4: 1 | B4: =ROUNDUP(A4/12,0) -> 1 | C4: =Inputs!B13 -> 0.707 | D4: =IF(Inputs!$B$16="Linear",MIN(Inputs!$B$14,Inputs!$B$13+(Inputs!$B$14-Inputs!$B$13)*A4/Inputs!$B$15),IF(Inputs!$B$16="S-Curve",Inputs!$B$13+(Inputs!$B$14-Inputs!$B$13)/(1+EXP(-0.25*(A4-Inputs!$B$15/2))),Inputs!$B$13+(Inputs!$B$14-Inputs!$B$13)/(1+EXP(-0.35*(A4-Inputs!$B$15/2))))) -> 0.71806357 | E4: =MIN(Inputs!$B$14,D4) -> 0.71806357 | F4: ='Unit Mix & Market Comps'!$B$11*E4 -> 362.6221 | G4: =MAX(0,E4-Inputs!$B$17) -> 0.68806357 | H4: =Inputs!$B$18/12 -> 0.0041666667 | I4: ='Unit Mix & Market Comps'!$E$11*(1+H4)^(A4-1) -> 205.84158 | J4: ='Unit Mix & Market Comps'!$B$11*I4*G4 -> 71524.208 | K4: =J4*(Inputs!$B$19+Inputs!$B$20)+Inputs!$B$21 -> 8937.1787 | L4: =J4+K4 -> 80461.386
A5: 2 | B5: =ROUNDUP(A5/12,0) -> 1 | C5: =E4 -> 0.71806357 | D5: =IF(Inputs!$B$16="Linear",MIN(Inputs!$B$14,Inputs!$B$13+(Inputs!$B$14-Inputs!$B$13)*A5/Inputs!$B$15),IF(Inputs!$B$16="S-Curve",Inputs!$B$13+(Inputs!$B$14-Inputs!$B$13)/(1+EXP(-0.25*(A5-Inputs!$B$15/2))),Inputs!$B$13+(Inputs!$B$14-Inputs!$B$13)/(1+EXP(-0.35*(A5-Inputs!$B$15/2))))) -> 0.72233164 | E5: =MIN(Inputs!$B$14,D5) -> 0.72233164 | F5: ='Unit Mix & Market Comps'!$B$11*E5 -> 364.77748 | G5: =MAX(0,E5-Inputs!$B$17) -> 0.69233164 | H5: =Inputs!$B$18/12 -> 0.0041666667 | I5: ='Unit Mix & Market Comps'!$E$11*(1+H5)^(A5-1) -> 206.69926 | J5: ='Unit Mix & Market Comps'!$B$11*I5*G5 -> 72267.74 | K5: =J5*(Inputs!$B$19+Inputs!$B$20)+Inputs!$B$21 -> 9004.0966 | L5: =J5+K5 -> 81271.837
A6: 3 | B6: =ROUNDUP(A6/12,0) -> 1 | C6: =E5 -> 0.72233164 | D6: =IF(Inputs!$B$16="Linear",MIN(Inputs!$B$14,Inputs!$B$13+(Inputs!$B$14-Inputs!$B$13)*A6/Inputs!$B$15),IF(Inputs!$B$16="S-Curve",Inputs!$B$13+(Inputs!$B$14-Inputs!$B$13)/(1+EXP(-0.25*(A6-Inputs!$B$15/2))),Inputs!$B$13+(Inputs!$B$14-Inputs!$B$13)/(1+EXP(-0.35*(A6-Inputs!$B$15/2))))) -> 0.72805569 | E6: =MIN(Inputs!$B$14,D6) -> 0.72805569 | F6: ='Unit Mix & Market Comps'!$B$11*E6 -> 367.66812 | G6: =MAX(0,E6-Inputs!$B$17) -> 0.69805569 | H6: =Inputs!$B$18/12 -> 0.0041666667 | I6: ='Unit Mix & Market Comps'!$E$11*(1+H6)^(A6-1) -> 207.5605 | J6: ='Unit Mix & Market Comps'!$B$11*I6*G6 -> 73168.839 | K6: =J6*(Inputs!$B$19+Inputs!$B$20)+Inputs!$B$21 -> 9085.1955 | L6: =J6+K6 -> 82254.035
A7: 4 | B7: =ROUNDUP(A7/12,0) -> 1 | C7: =E6 -> 0.72805569 | D7: =IF(Inputs!$B$16="Linear",MIN(Inputs!$B$14,Inputs!$B$13+(Inputs!$B$14-Inputs!$B$13)*A7/Inputs!$B$15),IF(Inputs!$B$16="S-Curve",Inputs!$B$13+(Inputs!$B$14-Inputs!$B$13)/(1+EXP(-0.25*(A7-Inputs!$B$15/2))),Inputs!$B$13+(Inputs!$B$14-Inputs!$B$13)/(1+EXP(-0.35*(A7-Inputs!$B$15/2))))) -> 0.73557311 | E7: =MIN(Inputs!$B$14,D7) -> 0.73557311 | F7: ='Unit Mix & Market Comps'!$B$11*E7 -> 371.46442 | G7: =MAX(0,E7-Inputs!$B$17) -> 0.70557311 | H7: =Inputs!$B$18/12 -> 0.0041666667 | I7: ='Unit Mix & Market Comps'!$E$11*(1+H7)^(A7-1) -> 208.42534 | J7: ='Unit Mix & Market Comps'!$B$11*I7*G7 -> 74264.954 | K7: =J7*(Inputs!$B$19+Inputs!$B$20)+Inputs!$B$21 -> 9183.8459 | L7: =J7+K7 -> 83448.8
A8: 5 | B8: =ROUNDUP(A8/12,0) -> 1 | C8: =E7 -> 0.73557311 | D8: =IF(Inputs!$B$16="Linear",MIN(Inputs!$B$14,Inputs!$B$13+(Inputs!$B$14-Inputs!$B$13)*A8/Inputs!$B$15),IF(Inputs!$B$16="S-Curve",Inputs!$B$13+(Inputs!$B$14-Inputs!$B$13)/(1+EXP(-0.25*(A8-Inputs!$B$15/2))),Inputs!$B$13+(Inputs!$B$14-Inputs!$B$13)/(1+EXP(-0.35*(A8-Inputs!$B$15/2))))) -> 0.74517851 | E8: =MIN(Inputs!$B$14,D8) -> 0.74517851 | F8: ='Unit Mix & Market Comps'!$B$11*E8 -> 376.31515 | G8: =MAX(0,E8-Inputs!$B$17) -> 0.71517851 | H8: =Inputs!$B$18/12 -> 0.0041666667 | I8: ='Unit Mix & Market Comps'!$E$11*(1+H8)^(A8-1) -> 209.29378 | J8: ='Unit Mix & Market Comps'!$B$11*I8*G8 -> 75589.618 | K8: =J8*(Inputs!$B$19+Inputs!$B$20)+Inputs!$B$21 -> 9303.0657 | L8: =J8+K8 -> 84892.684
A9: 6 | B9: =ROUNDUP(A9/12,0) -> 1 | C9: =E8 -> 0.74517851 | D9: =IF(Inputs!$B$16="Linear",MIN(Inputs!$B$14,Inputs!$B$13+(Inputs!$B$14-Inputs!$B$13)*A9/Inputs!$B$15),IF(Inputs!$B$16="S-Curve",Inputs!$B$13+(Inputs!$B$14-Inputs!$B$13)/(1+EXP(-0.25*(A9-Inputs!$B$15/2))),Inputs!$B$13+(Inputs!$B$14-Inputs!$B$13)/(1+EXP(-0.35*(A9-Inputs!$B$15/2))))) -> 0.75703044 | E9: =MIN(Inputs!$B$14,D9) -> 0.75703044 | F9: ='Unit Mix & Market Comps'!$B$11*E9 -> 382.30037 | G9: =MAX(0,E9-Inputs!$B$17) -> 0.72703044 | H9: =Inputs!$B$18/12 -> 0.0041666667 | I9: ='Unit Mix & Market Comps'!$E$11*(1+H9)^(A9-1) -> 210.16584 | J9: ='Unit Mix & Market Comps'!$B$11*I9*G9 -> 77162.465 | K9: =J9*(Inputs!$B$19+Inputs!$B$20)+Inputs!$B$21 -> 9444.6219 | L9: =J9+K9 -> 86607.087
A10: 7 | B10: =ROUNDUP(A10/12,0) -> 1 | C10: =E9 -> 0.75703044 | D10: =IF(Inputs!$B$16="Linear",MIN(Inputs!$B$14,Inputs!$B$13+(Inputs!$B$14-Inputs!$B$13)*A10/Inputs!$B$15),IF(Inputs!$B$16="S-Curve",Inputs!$B$13+(Inputs!$B$14-Inputs!$B$13)/(1+EXP(-0.25*(A10-Inputs!$B$15/2))),Inputs!$B$13+(Inputs!$B$14-Inputs!$B$13)/(1+EXP(-0.35*(A10-Inputs!$B$15/2))))) -> 0.77103976 | E10: =MIN(Inputs!$B$14,D10) -> 0.77103976 | F10: ='Unit Mix & Market Comps'!$B$11*E10 -> 389.37508 | G10: =MAX(0,E10-Inputs!$B$17) -> 0.74103976 | H10: =Inputs!$B$18/12 -> 0.0041666667 | I10: ='Unit Mix & Market Comps'!$E$11*(1+H10)^(A10-1) -> 211.04153 | J10: ='Unit Mix & Market Comps'!$B$11*I10*G10 -> 78977.032 | K10: =J10*(Inputs!$B$19+Inputs!$B$20)+Inputs!$B$21 -> 9607.9329 | L10: =J10+K10 -> 88584.965
A11: 8 | B11: =ROUNDUP(A11/12,0) -> 1 | C11: =E10 -> 0.77103976 | D11: =IF(Inputs!$B$16="Linear",MIN(Inputs!$B$14,Inputs!$B$13+(Inputs!$B$14-Inputs!$B$13)*A11/Inputs!$B$15),IF(Inputs!$B$16="S-Curve",Inputs!$B$13+(Inputs!$B$14-Inputs!$B$13)/(1+EXP(-0.25*(A11-Inputs!$B$15/2))),Inputs!$B$13+(Inputs!$B$14-Inputs!$B$13)/(1+EXP(-0.35*(A11-Inputs!$B$15/2))))) -> 0.78678281 | E11: =MIN(Inputs!$B$14,D11) -> 0.78678281 | F11: ='Unit Mix & Market Comps'!$B$11*E11 -> 397.32532 | G11: =MAX(0,E11-Inputs!$B$17) -> 0.75678281 | H11: =Inputs!$B$18/12 -> 0.0041666667 | I11: ='Unit Mix & Market Comps'!$E$11*(1+H11)^(A11-1) -> 211.92087 | J11: ='Unit Mix & Market Comps'!$B$11*I11*G11 -> 80990.925 | K11: =J11*(Inputs!$B$19+Inputs!$B$20)+Inputs!$B$21 -> 9789.1832 | L11: =J11+K11 -> 90780.108
A12: 9 | B12: =ROUNDUP(A12/12,0) -> 1 | C12: =E11 -> 0.78678281 | D12: =IF(Inputs!$B$16="Linear",MIN(Inputs!$B$14,Inputs!$B$13+(Inputs!$B$14-Inputs!$B$13)*A12/Inputs!$B$15),IF(Inputs!$B$16="S-Curve",Inputs!$B$13+(Inputs!$B$14-Inputs!$B$13)/(1+EXP(-0.25*(A12-Inputs!$B$15/2))),Inputs!$B$13+(Inputs!$B$14-Inputs!$B$13)/(1+EXP(-0.35*(A12-Inputs!$B$15/2))))) -> 0.8035 | E12: =MIN(Inputs!$B$14,D12) -> 0.8035 | F12: ='Unit Mix & Market Comps'!$B$11*E12 -> 405.7675 | G12: =MAX(0,E12-Inputs!$B$17) -> 0.7735 | H12: =Inputs!$B$18/12 -> 0.0041666667 | I12: ='Unit Mix & Market Comps'!$E$11*(1+H12)^(A12-1) -> 212.80387 | J12: ='Unit Mix & Market Comps'!$B$11*I12*G12 -> 83124.916 | K12: =J12*(Inputs!$B$19+Inputs!$B$20)+Inputs!$B$21 -> 9981.2424 | L12: =J12+K12 -> 93106.158
A13: 10 | B13: =ROUNDUP(A13/12,0) -> 1 | C13: =E12 -> 0.8035 | D13: =IF(Inputs!$B$16="Linear",MIN(Inputs!$B$14,Inputs!$B$13+(Inputs!$B$14-Inputs!$B$13)*A13/Inputs!$B$15),IF(Inputs!$B$16="S-Curve",Inputs!$B$13+(Inputs!$B$14-Inputs!$B$13)/(1+EXP(-0.25*(A13-Inputs!$B$15/2))),Inputs!$B$13+(Inputs!$B$14-Inputs!$B$13)/(1+EXP(-0.35*(A13-Inputs!$B$15/2))))) -> 0.82021719 | E13: =MIN(Inputs!$B$14,D13) -> 0.82021719 | F13: ='Unit Mix & Market Comps'!$B$11*E13 -> 414.20968 | G13: =MAX(0,E13-Inputs!$B$17) -> 0.79021719 | H13: =Inputs!$B$18/12 -> 0.0041666667 | I13: ='Unit Mix & Market Comps'!$E$11*(1+H13)^(A13-1) -> 213.69055 | J13: ='Unit Mix & Market Comps'!$B$11*I13*G13 -> 85275.284 | K13: =J13*(Inputs!$B$19+Inputs!$B$20)+Inputs!$B$21 -> 10174.776 | L13: =J13+K13 -> 95450.06
A14: 11 | B14: =ROUNDUP(A14/12,0) -> 1 | C14: =E13 -> 0.82021719 | D14: =IF(Inputs!$B$16="Linear",MIN(Inputs!$B$14,Inputs!$B$13+(Inputs!$B$14-Inputs!$B$13)*A14/Inputs!$B$15),IF(Inputs!$B$16="S-Curve",Inputs!$B$13+(Inputs!$B$14-Inputs!$B$13)/(1+EXP(-0.25*(A14-Inputs!$B$15/2))),Inputs!$B$13+(Inputs!$B$14-Inputs!$B$13)/(1+EXP(-0.35*(A14-Inputs!$B$15/2))))) -> 0.83596024 | E14: =MIN(Inputs!$B$14,D14) -> 0.83596024 | F14: ='Unit Mix & Market Comps'!$B$11*E14 -> 422.15992 | G14: =MAX(0,E14-Inputs!$B$17) -> 0.80596024 | H14: =Inputs!$B$18/12 -> 0.0041666667 | I14: ='Unit Mix & Market Comps'!$E$11*(1+H14)^(A14-1) -> 214.58093 | J14: ='Unit Mix & Market Comps'!$B$11*I14*G14 -> 87336.568 | K14: =J14*(Inputs!$B$19+Inputs!$B$20)+Inputs!$B$21 -> 10360.291 | L14: =J14+K14 -> 97696.859
A15: 12 | B15: =ROUNDUP(A15/12,0) -> 1 | C15: =E14 -> 0.83596024 | D15: =IF(Inputs!$B$16="Linear",MIN(Inputs!$B$14,Inputs!$B$13+(Inputs!$B$14-Inputs!$B$13)*A15/Inputs!$B$15),IF(Inputs!$B$16="S-Curve",Inputs!$B$13+(Inputs!$B$14-Inputs!$B$13)/(1+EXP(-0.25*(A15-Inputs!$B$15/2))),Inputs!$B$13+(Inputs!$B$14-Inputs!$B$13)/(1+EXP(-0.35*(A15-Inputs!$B$15/2))))) -> 0.84996956 | E15: =MIN(Inputs!$B$14,D15) -> 0.84996956 | F15: ='Unit Mix & Market Comps'!$B$11*E15 -> 429.23463 | G15: =MAX(0,E15-Inputs!$B$17) -> 0.81996956 | H15: =Inputs!$B$18/12 -> 0.0041666667 | I15: ='Unit Mix & Market Comps'!$E$11*(1+H15)^(A15-1) -> 215.47502 | J15: ='Unit Mix & Market Comps'!$B$11*I15*G15 -> 89224.892 | K15: =J15*(Inputs!$B$19+Inputs!$B$20)+Inputs!$B$21 -> 10530.24 | L15: =J15+K15 -> 99755.132
A16: 13 | B16: =ROUNDUP(A16/12,0) -> 2 | C16: =E15 -> 0.84996956 | D16: =IF(Inputs!$B$16="Linear",MIN(Inputs!$B$14,Inputs!$B$13+(Inputs!$B$14-Inputs!$B$13)*A16/Inputs!$B$15),IF(Inputs!$B$16="S-Curve",Inputs!$B$13+(Inputs!$B$14-Inputs!$B$13)/(1+EXP(-0.25*(A16-Inputs!$B$15/2))),Inputs!$B$13+(Inputs!$B$14-Inputs!$B$13)/(1+EXP(-0.35*(A16-Inputs!$B$15/2))))) -> 0.86182149 | E16: =MIN(Inputs!$B$14,D16) -> 0.86182149 | F16: ='Unit Mix & Market Comps'!$B$11*E16 -> 435.21985 | G16: =MAX(0,E16-Inputs!$B$17) -> 0.83182149 | H16: =Inputs!$B$18/12 -> 0.0041666667 | I16: ='Unit Mix & Market Comps'!$E$11*(1+H16)^(A16-1) -> 216.37283 | J16: ='Unit Mix & Market Comps'!$B$11*I16*G16 -> 90891.703 | K16: =J16*(Inputs!$B$19+Inputs!$B$20)+Inputs!$B$21 -> 10680.253 | L16: =J16+K16 -> 101571.96
... A63: 60 | B63: =ROUNDUP(A63/12,0) -> 5 | C63: =E62 -> 0.9 | D63: =IF(Inputs!$B$16="Linear",MIN(Inputs!$B$14,Inputs!$B$13+(Inputs!$B$14-Inputs!$B$13)*A63/Inputs!$B$15),IF(Inputs!$B$16="S-Curve",Inputs!$B$13+(Inputs!$B$14-Inputs!$B$13)/(1+EXP(-0.25*(A63-Inputs!$B$15/2))),Inputs!$B$13+(Inputs!$B$14-Inputs!$B$13)/(1+EXP(-0.35*(A63-Inputs!$B$15/2))))) -> 0.9 | E63: =MIN(Inputs!$B$14,D63) -> 0.9 | F63: ='Unit Mix & Market Comps'!$B$11*E63 -> 454.5 | G63: =MAX(0,E63-Inputs!$B$17) -> 0.87 | H63: =Inputs!$B$18/12 -> 0.0041666667 | I63: ='Unit Mix & Market Comps'!$E$11*(1+H63)^(A63-1) -> 263.07245 | J63: ='Unit Mix & Market Comps'!$B$11*I63*G63 -> 115580.88 | K63: =J63*(Inputs!$B$19+Inputs!$B$20)+Inputs!$B$21 -> 12902.279 | L63: =J63+K63 -> 128483.16

Sheet Revenue Forecast
A1: Annual Revenue Forecast
A3: Year | B3: Avg Economic Occ. | C3: Rental Revenue | D3: Ancillary Income | E3: Expansion Revenue | F3: Total EGI | G3: EGI Growth
A4: 1 | B4: =AVERAGE('Monthly Lease-Up'!G4:G15) -> 0.74280854 | C4: =SUM('Monthly Lease-Up'!J4:J15) -> 948907.44 | D4: =SUM('Monthly Lease-Up'!K4:K15) -> 115401.67 | E4: =SUM('Expansion CapEx'!E17:E28) -> 0 | F4: =C4+D4+E4 -> 1064309.1 | G4: -
A5: 2 | B5: =AVERAGE('Monthly Lease-Up'!G16:G27) -> 0.85840705 | C5: =SUM('Monthly Lease-Up'!J16:J27) -> 1151917.8 | D5: =SUM('Monthly Lease-Up'!K16:K27) -> 133672.61 | E5: =SUM('Expansion CapEx'!E29:E40) -> 0 | F5: =C5+D5+E5 -> 1285590.5 | G5: =F5/F4-1 -> 0.20791079
A6: 3 | B6: =AVERAGE('Monthly Lease-Up'!G28:G39) -> 0.86980206 | C6: =SUM('Monthly Lease-Up'!J28:J39) -> 1226714.2 | D6: =SUM('Monthly Lease-Up'!K28:K39) -> 140404.28 | E6: =SUM('Expansion CapEx'!E41:E52) -> 127050 | F6: =C6+D6+E6 -> 1494168.5 | G6: =F6/F5-1 -> 0.16224296
A7: 4 | B7: =AVERAGE('Monthly Lease-Up'!G40:G51) -> 0.86999703 | C7: =SUM('Monthly Lease-Up'!J40:J51) -> 1289760.3 | D7: =SUM('Monthly Lease-Up'!K40:K51) -> 146078.43 | E7: =SUM('Expansion CapEx'!E53:E64) -> 277200 | F7: =C7+D7+E7 -> 1713038.7 | G7: =F7/F6-1 -> 0.14648299
A8: 5 | B8: =AVERAGE('Monthly Lease-Up'!G52:G63) -> 0.86999996 | C8: =SUM('Monthly Lease-Up'!J52:J63) -> 1355751.4 | D8: =SUM('Monthly Lease-Up'!K52:K63) -> 152017.62 | E8: =SUM('Expansion CapEx'!E65:E76) -> 277200 | F8: =C8+D8+E8 -> 1784969 | G8: =F8/F7-1 -> 0.041989877

Sheet Operating Expenses
A1: Operating Expense Forecast
A4: Expense Line | B4: Year 1 | C4: Year 2 | D4: Year 3 | E4: Year 4 | F4: Year 5 | G4: % EGI Y1
A5: Property Taxes | B5: 130000 | C5: =B5*(1+Inputs!$B$22)^1 -> 133250 | D5: =B5*(1+Inputs!$B$22)^2 -> 136581.25 | E5: =B5*(1+Inputs!$B$22)^3 -> 139995.78 | F5: =B5*(1+Inputs!$B$22)^4 -> 143495.68 | G5: =B5/'Revenue Forecast'!$F$4 -> 0.12214497
A6: Insurance | B6: 45000 | C6: =B6*(1+Inputs!$B$22)^1 -> 46125 | D6: =B6*(1+Inputs!$B$22)^2 -> 47278.125 | E6: =B6*(1+Inputs!$B$22)^3 -> 48460.078 | F6: =B6*(1+Inputs!$B$22)^4 -> 49671.58 | G6: =B6/'Revenue Forecast'!$F$4 -> 0.04228095
A7: Utilities | B7: 60000 | C7: =B7*(1+Inputs!$B$22)^1 -> 61500 | D7: =B7*(1+Inputs!$B$22)^2 -> 63037.5 | E7: =B7*(1+Inputs!$B$22)^3 -> 64613.437 | F7: =B7*(1+Inputs!$B$22)^4 -> 66228.773 | G7: =B7/'Revenue Forecast'!$F$4 -> 0.0563746
A8: Repairs & Maintenance | B8: 65000 | C8: =B8*(1+Inputs!$B$22)^1 -> 66625 | D8: =B8*(1+Inputs!$B$22)^2 -> 68290.625 | E8: =B8*(1+Inputs!$B$22)^3 -> 69997.891 | F8: =B8*(1+Inputs!$B$22)^4 -> 71747.838 | G8: =B8/'Revenue Forecast'!$F$4 -> 0.061072483
A9: Payroll / On-Site Staff | B9: 90000 | C9: =B9*(1+Inputs!$B$22)^1 -> 92250 | D9: =B9*(1+Inputs!$B$22)^2 -> 94556.25 | E9: =B9*(1+Inputs!$B$22)^3 -> 96920.156 | F9: =B9*(1+Inputs!$B$22)^4 -> 99343.16 | G9: =B9/'Revenue Forecast'!$F$4 -> 0.084561899
A10: Management Fee | B10: ='Revenue Forecast'!F4*3.5% -> 37250.819 | C10: =B10*(1+Inputs!$B$22)^1 -> 38182.089 | D10: =B10*(1+Inputs!$B$22)^2 -> 39136.642 | E10: =B10*(1+Inputs!$B$22)^3 -> 40115.058 | F10: =B10*(1+Inputs!$B$22)^4 -> 41117.934 | G10: =B10/'Revenue Forecast'!$F$4 -> 0.035
A11: Marketing / Admin | B11: 40000 | C11: =B11*(1+Inputs!$B$22)^1 -> 41000 | D11: =B11*(1+Inputs!$B$22)^2 -> 42025 | E11: =B11*(1+Inputs!$B$22)^3 -> 43075.625 | F11: =B11*(1+Inputs!$B$22)^4 -> 44152.516 | G11: =B11/'Revenue Forecast'!$F$4 -> 0.037583066
A12: Software / Call Center | B12: 30000 | C12: =B12*(1+Inputs!$B$22)^1 -> 30750 | D12: =B12*(1+Inputs!$B$22)^2 -> 31518.75 | E12: =B12*(1+Inputs!$B$22)^3 -> 32306.719 | F12: =B12*(1+Inputs!$B$22)^4 -> 33114.387 | G12: =B12/'Revenue Forecast'!$F$4 -> 0.0281873
A13: Bad Debt / Concessions | B13: ='Revenue Forecast'!F4*1.5% -> 15964.637 | C13: =B13*(1+Inputs!$B$22)^1 -> 16363.753 | D13: =B13*(1+Inputs!$B$22)^2 -> 16772.846 | E13: =B13*(1+Inputs!$B$22)^3 -> 17192.168 | F13: =B13*(1+Inputs!$B$22)^4 -> 17621.972 | G13: =B13/'Revenue Forecast'!$F$4 -> 0.015
A14: Replacement Reserves | B14: 25000 | C14: =B14*(1+Inputs!$B$22)^1 -> 25625 | D14: =B14*(1+Inputs!$B$22)^2 -> 26265.625 | E14: =B14*(1+Inputs!$B$22)^3 -> 26922.266 | F14: =B14*(1+Inputs!$B$22)^4 -> 27595.322 | G14: =B14/'Revenue Forecast'!$F$4 -> 0.023489417
A15: Total Operating Expenses | B15: =SUM(B5:B14) -> 538215.46 | C15: =SUM(C5:C14) -> 551670.84 | D15: =SUM(D5:D14) -> 565462.61 | E15: =SUM(E5:E14) -> 579599.18 | F15: =SUM(F5:F14) -> 594089.16 | G15: =B15/'Revenue Forecast'!$F$4 -> 0.50569468
A17: NOI | B17: ='Revenue Forecast'!F4-B15 -> 526093.66 | C17: ='Revenue Forecast'!F5-C15 -> 733919.61 | D17: ='Revenue Forecast'!F6-D15 -> 928705.84 | E17: ='Revenue Forecast'!F7-E15 -> 1133439.5 | F17: ='Revenue Forecast'!F8-F15 -> 1190879.8 | G17: =B17/'Revenue Forecast'!$F$4 -> 0.49430532

Sheet Expansion CapEx
A1: Expansion / Construction Module
A3: Expansion Assumptions
A4: Expansion Enabled? | B4: 1
A5: Expansion Start Month | B5: 13
A6: Construction Duration Months | B6: 12
A7: New Rentable Units | B7: 150
A8: Avg New Unit Monthly Rent | B8: 175
A9: Stabilized Occ. on New Units | B9: 0.88
A10: Cost Per New Unit | B10: 8500
A11: Soft Costs % | B11: 0.12
A12: Contingency % | B12: 0.1
A16: Month | B16: Construction Spend | C16: Cumulative Spend | D16: New Unit Occ. | E16: New Unit Revenue | F16: Incremental NOI @ 65% Margin
A17: 1 | B17: =IF(AND($B$4=1,A17>=$B$5,A17<$B$5+$B$6),($B$7*$B$10*(1+$B$11+$B$12))/$B$6,0) -> 0 | C17: =SUM($B$17:B17) -> 0 | D17: =IF(A17<$B$5+$B$6,0,MIN($B$9,(A17-($B$5+$B$6))/12*$B$9)) -> 0 | E17: =$B$7*$B$8*D17 -> 0 | F17: =E17*65% -> 0
A18: 2 | B18: =IF(AND($B$4=1,A18>=$B$5,A18<$B$5+$B$6),($B$7*$B$10*(1+$B$11+$B$12))/$B$6,0) -> 0 | C18: =SUM($B$17:B18) -> 0 | D18: =IF(A18<$B$5+$B$6,0,MIN($B$9,(A18-($B$5+$B$6))/12*$B$9)) -> 0 | E18: =$B$7*$B$8*D18 -> 0 | F18: =E18*65% -> 0
A19: 3 | B19: =IF(AND($B$4=1,A19>=$B$5,A19<$B$5+$B$6),($B$7*$B$10*(1+$B$11+$B$12))/$B$6,0) -> 0 | C19: =SUM($B$17:B19) -> 0 | D19: =IF(A19<$B$5+$B$6,0,MIN($B$9,(A19-($B$5+$B$6))/12*$B$9)) -> 0 | E19: =$B$7*$B$8*D19 -> 0 | F19: =E19*65% -> 0
A20: 4 | B20: =IF(AND($B$4=1,A20>=$B$5,A20<$B$5+$B$6),($B$7*$B$10*(1+$B$11+$B$12))/$B$6,0) -> 0 | C20: =SUM($B$17:B20) -> 0 | D20: =IF(A20<$B$5+$B$6,0,MIN($B$9,(A20-($B$5+$B$6))/12*$B$9)) -> 0 | E20: =$B$7*$B$8*D20 -> 0 | F20: =E20*65% -> 0
A21: 5 | B21: =IF(AND($B$4=1,A21>=$B$5,A21<$B$5+$B$6),($B$7*$B$10*(1+$B$11+$B$12))/$B$6,0) -> 0 | C21: =SUM($B$17:B21) -> 0 | D21: =IF(A21<$B$5+$B$6,0,MIN($B$9,(A21-($B$5+$B$6))/12*$B$9)) -> 0 | E21: =$B$7*$B$8*D21 -> 0 | F21: =E21*65% -> 0
A22: 6 | B22: =IF(AND($B$4=1,A22>=$B$5,A22<$B$5+$B$6),($B$7*$B$10*(1+$B$11+$B$12))/$B$6,0) -> 0 | C22: =SUM($B$17:B22) -> 0 | D22: =IF(A22<$B$5+$B$6,0,MIN($B$9,(A22-($B$5+$B$6))/12*$B$9)) -> 0 | E22: =$B$7*$B$8*D22 -> 0 | F22: =E22*65% -> 0
A23: 7 | B23: =IF(AND($B$4=1,A23>=$B$5,A23<$B$5+$B$6),($B$7*$B$10*(1+$B$11+$B$12))/$B$6,0) -> 0 | C23: =SUM($B$17:B23) -> 0 | D23: =IF(A23<$B$5+$B$6,0,MIN($B$9,(A23-($B$5+$B$6))/12*$B$9)) -> 0 | E23: =$B$7*$B$8*D23 -> 0 | F23: =E23*65% -> 0
A24: 8 | B24: =IF(AND($B$4=1,A24>=$B$5,A24<$B$5+$B$6),($B$7*$B$10*(1+$B$11+$B$12))/$B$6,0) -> 0 | C24: =SUM($B$17:B24) -> 0 | D24: =IF(A24<$B$5+$B$6,0,MIN($B$9,(A24-($B$5+$B$6))/12*$B$9)) -> 0 | E24: =$B$7*$B$8*D24 -> 0 | F24: =E24*65% -> 0
A25: 9 | B25: =IF(AND($B$4=1,A25>=$B$5,A25<$B$5+$B$6),($B$7*$B$10*(1+$B$11+$B$12))/$B$6,0) -> 0 | C25: =SUM($B$17:B25) -> 0 | D25: =IF(A25<$B$5+$B$6,0,MIN($B$9,(A25-($B$5+$B$6))/12*$B$9)) -> 0 | E25: =$B$7*$B$8*D25 -> 0 | F25: =E25*65% -> 0
A26: 10 | B26: =IF(AND($B$4=1,A26>=$B$5,A26<$B$5+$B$6),($B$7*$B$10*(1+$B$11+$B$12))/$B$6,0) -> 0 | C26: =SUM($B$17:B26) -> 0 | D26: =IF(A26<$B$5+$B$6,0,MIN($B$9,(A26-($B$5+$B$6))/12*$B$9)) -> 0 | E26: =$B$7*$B$8*D26 -> 0 | F26: =E26*65% -> 0
A27: 11 | B27: =IF(AND($B$4=1,A27>=$B$5,A27<$B$5+$B$6),($B$7*$B$10*(1+$B$11+$B$12))/$B$6,0) -> 0 | C27: =SUM($B$17:B27) -> 0 | D27: =IF(A27<$B$5+$B$6,0,MIN($B$9,(A27-($B$5+$B$6))/12*$B$9)) -> 0 | E27: =$B$7*$B$8*D27 -> 0 | F27: =E27*65% -> 0
A28: 12 | B28: =IF(AND($B$4=1,A28>=$B$5,A28<$B$5+$B$6),($B$7*$B$10*(1+$B$11+$B$12))/$B$6,0) -> 0 | C28: =SUM($B$17:B28) -> 0 | D28: =IF(A28<$B$5+$B$6,0,MIN($B$9,(A28-($B$5+$B$6))/12*$B$9)) -> 0 | E28: =$B$7*$B$8*D28 -> 0 | F28: =E28*65% -> 0
... A76: 60 | B76: =IF(AND($B$4=1,A76>=$B$5,A76<$B$5+$B$6),($B$7*$B$10*(1+$B$11+$B$12))/$B$6,0) -> 0 | C76: =SUM($B$17:B76) -> 1555500 | D76: =IF(A76<$B$5+$B$6,0,MIN($B$9,(A76-($B$5+$B$6))/12*$B$9)) -> 0.88 | E76: =$B$7*$B$8*D76 -> 23100 | F76: =E76*65% -> 15015

Sheet Debt & Refi
A1: Debt Schedule / Refinance Scenario
A3: Initial Debt Sizing
A4: Total Project Cost | B4: =Inputs!B4*(1+Inputs!B5)+Inputs!B6+Inputs!B7*Inputs!B4 -> 4612500
A5: Initial Loan Amount | B5: =IF(Inputs!$B$49="Yes",0,Inputs!B4*Inputs!B25) -> 0
A6: Initial Equity Required | B6: =B4-B5 -> 4612500
A7: Annual Debt Service | B7: =IF(Inputs!$B$49="Yes",0,PMT(Inputs!B26/12,Inputs!B27*12,-B5)*12) -> 0
A8: Debt Yield - Year 1 | B8: =IF(OR(Inputs!$B$49="Yes",$B$5=0),"N/A",'Operating Expenses'!B17/$B$5) -> N/A
A9: DSCR - Year 1 | B9: =IF(OR(Inputs!$B$49="Yes",$B$7=0),"N/A",'Operating Expenses'!B17/$B$7) -> N/A
A11: Debt Toggle | B11: =Inputs!B50 -> Levered
A13: Month | B13: Beginning Loan | C13: Scheduled Debt Service | D13: Interest | E13: Principal | F13: Ending Loan | G13: Refi Value | H13: Refi Loan | I13: Refi Proceeds | J13: Active Loan Balance
A14: 1 | B14: =IF(Inputs!$B$49="Yes",0,$B$5) -> 0 | C14: =IF(Inputs!$B$49="Yes",0,IF(A14<Inputs!$B$28,Inputs!$B$26/12*B14,PMT(Inputs!$B$26/12,Inputs!$B$27*12,-B14))) -> 0 | D14: =IF(Inputs!$B$49="Yes",0,B14*Inputs!$B$26/12) -> 0 | E14: =IF(Inputs!$B$49="Yes",0,MAX(0,C14-D14)) -> 0 | F14: =IF(Inputs!$B$49="Yes",0,MAX(0,B14-E14)) -> 0 | G14: =IF(Inputs!$B$49="Yes",0,IF(A14=Inputs!$B$30,('Operating Expenses'!D17*4)/Inputs!$B$35,0)) -> 0 | H14: =IF(Inputs!$B$49="Yes",0,IF(A14=Inputs!$B$30,G14*Inputs!$B$31,0)) -> 0 | I14: =IF(Inputs!$B$49="Yes",0,IF(A14=Inputs!$B$30,MAX(0,H14-F14),0)) -> 0 | J14: =IF(Inputs!$B$49="Yes",0,IF(A14=Inputs!$B$30,H14,F14)) -> 0
A15: 2 | B15: =IF(Inputs!$B$49="Yes",0,J14) -> 0 | C15: =IF(Inputs!$B$49="Yes",0,IF(A15<Inputs!$B$28,Inputs!$B$26/12*B15,PMT(Inputs!$B$26/12,Inputs!$B$27*12,-B15))) -> 0 | D15: =IF(Inputs!$B$49="Yes",0,B15*Inputs!$B$26/12) -> 0 | E15: =IF(Inputs!$B$49="Yes",0,MAX(0,C15-D15)) -> 0 | F15: =IF(Inputs!$B$49="Yes",0,MAX(0,B15-E15)) -> 0 | G15: =IF(Inputs!$B$49="Yes",0,IF(A15=Inputs!$B$30,('Operating Expenses'!D17*4)/Inputs!$B$35,0)) -> 0 | H15: =IF(Inputs!$B$49="Yes",0,IF(A15=Inputs!$B$30,G15*Inputs!$B$31,0)) -> 0 | I15: =IF(Inputs!$B$49="Yes",0,IF(A15=Inputs!$B$30,MAX(0,H15-F15),0)) -> 0 | J15: =IF(Inputs!$B$49="Yes",0,IF(A15=Inputs!$B$30,H15,F15)) -> 0
A16: 3 | B16: =IF(Inputs!$B$49="Yes",0,J15) -> 0 | C16: =IF(Inputs!$B$49="Yes",0,IF(A16<Inputs!$B$28,Inputs!$B$26/12*B16,PMT(Inputs!$B$26/12,Inputs!$B$27*12,-B16))) -> 0 | D16: =IF(Inputs!$B$49="Yes",0,B16*Inputs!$B$26/12) -> 0 | E16: =IF(Inputs!$B$49="Yes",0,MAX(0,C16-D16)) -> 0 | F16: =IF(Inputs!$B$49="Yes",0,MAX(0,B16-E16)) -> 0 | G16: =IF(Inputs!$B$49="Yes",0,IF(A16=Inputs!$B$30,('Operating Expenses'!D17*4)/Inputs!$B$35,0)) -> 0 | H16: =IF(Inputs!$B$49="Yes",0,IF(A16=Inputs!$B$30,G16*Inputs!$B$31,0)) -> 0 | I16: =IF(Inputs!$B$49="Yes",0,IF(A16=Inputs!$B$30,MAX(0,H16-F16),0)) -> 0 | J16: =IF(Inputs!$B$49="Yes",0,IF(A16=Inputs!$B$30,H16,F16)) -> 0
A17: 4 | B17: =IF(Inputs!$B$49="Yes",0,J16) -> 0 | C17: =IF(Inputs!$B$49="Yes",0,IF(A17<Inputs!$B$28,Inputs!$B$26/12*B17,PMT(Inputs!$B$26/12,Inputs!$B$27*12,-B17))) -> 0 | D17: =IF(Inputs!$B$49="Yes",0,B17*Inputs!$B$26/12) -> 0 | E17: =IF(Inputs!$B$49="Yes",0,MAX(0,C17-D17)) -> 0 | F17: =IF(Inputs!$B$49="Yes",0,MAX(0,B17-E17)) -> 0 | G17: =IF(Inputs!$B$49="Yes",0,IF(A17=Inputs!$B$30,('Operating Expenses'!D17*4)/Inputs!$B$35,0)) -> 0 | H17: =IF(Inputs!$B$49="Yes",0,IF(A17=Inputs!$B$30,G17*Inputs!$B$31,0)) -> 0 | I17: =IF(Inputs!$B$49="Yes",0,IF(A17=Inputs!$B$30,MAX(0,H17-F17),0)) -> 0 | J17: =IF(Inputs!$B$49="Yes",0,IF(A17=Inputs!$B$30,H17,F17)) -> 0
A18: 5 | B18: =IF(Inputs!$B$49="Yes",0,J17) -> 0 | C18: =IF(Inputs!$B$49="Yes",0,IF(A18<Inputs!$B$28,Inputs!$B$26/12*B18,PMT(Inputs!$B$26/12,Inputs!$B$27*12,-B18))) -> 0 | D18: =IF(Inputs!$B$49="Yes",0,B18*Inputs!$B$26/12) -> 0 | E18: =IF(Inputs!$B$49="Yes",0,MAX(0,C18-D18)) -> 0 | F18: =IF(Inputs!$B$49="Yes",0,MAX(0,B18-E18)) -> 0 | G18: =IF(Inputs!$B$49="Yes",0,IF(A18=Inputs!$B$30,('Operating Expenses'!D17*4)/Inputs!$B$35,0)) -> 0 | H18: =IF(Inputs!$B$49="Yes",0,IF(A18=Inputs!$B$30,G18*Inputs!$B$31,0)) -> 0 | I18: =IF(Inputs!$B$49="Yes",0,IF(A18=Inputs!$B$30,MAX(0,H18-F18),0)) -> 0 | J18: =IF(Inputs!$B$49="Yes",0,IF(A18=Inputs!$B$30,H18,F18)) -> 0
A19: 6 | B19: =IF(Inputs!$B$49="Yes",0,J18) -> 0 | C19: =IF(Inputs!$B$49="Yes",0,IF(A19<Inputs!$B$28,Inputs!$B$26/12*B19,PMT(Inputs!$B$26/12,Inputs!$B$27*12,-B19))) -> 0 | D19: =IF(Inputs!$B$49="Yes",0,B19*Inputs!$B$26/12) -> 0 | E19: =IF(Inputs!$B$49="Yes",0,MAX(0,C19-D19)) -> 0 | F19: =IF(Inputs!$B$49="Yes",0,MAX(0,B19-E19)) -> 0 | G19: =IF(Inputs!$B$49="Yes",0,IF(A19=Inputs!$B$30,('Operating Expenses'!D17*4)/Inputs!$B$35,0)) -> 0 | H19: =IF(Inputs!$B$49="Yes",0,IF(A19=Inputs!$B$30,G19*Inputs!$B$31,0)) -> 0 | I19: =IF(Inputs!$B$49="Yes",0,IF(A19=Inputs!$B$30,MAX(0,H19-F19),0)) -> 0 | J19: =IF(Inputs!$B$49="Yes",0,IF(A19=Inputs!$B$30,H19,F19)) -> 0
A20: 7 | B20: =IF(Inputs!$B$49="Yes",0,J19) -> 0 | C20: =IF(Inputs!$B$49="Yes",0,IF(A20<Inputs!$B$28,Inputs!$B$26/12*B20,PMT(Inputs!$B$26/12,Inputs!$B$27*12,-B20))) -> 0 | D20: =IF(Inputs!$B$49="Yes",0,B20*Inputs!$B$26/12) -> 0 | E20: =IF(Inputs!$B$49="Yes",0,MAX(0,C20-D20)) -> 0 | F20: =IF(Inputs!$B$49="Yes",0,MAX(0,B20-E20)) -> 0 | G20: =IF(Inputs!$B$49="Yes",0,IF(A20=Inputs!$B$30,('Operating Expenses'!D17*4)/Inputs!$B$35,0)) -> 0 | H20: =IF(Inputs!$B$49="Yes",0,IF(A20=Inputs!$B$30,G20*Inputs!$B$31,0)) -> 0 | I20: =IF(Inputs!$B$49="Yes",0,IF(A20=Inputs!$B$30,MAX(0,H20-F20),0)) -> 0 | J20: =IF(Inputs!$B$49="Yes",0,IF(A20=Inputs!$B$30,H20,F20)) -> 0
A21: 8 | B21: =IF(Inputs!$B$49="Yes",0,J20) -> 0 | C21: =IF(Inputs!$B$49="Yes",0,IF(A21<Inputs!$B$28,Inputs!$B$26/12*B21,PMT(Inputs!$B$26/12,Inputs!$B$27*12,-B21))) -> 0 | D21: =IF(Inputs!$B$49="Yes",0,B21*Inputs!$B$26/12) -> 0 | E21: =IF(Inputs!$B$49="Yes",0,MAX(0,C21-D21)) -> 0 | F21: =IF(Inputs!$B$49="Yes",0,MAX(0,B21-E21)) -> 0 | G21: =IF(Inputs!$B$49="Yes",0,IF(A21=Inputs!$B$30,('Operating Expenses'!D17*4)/Inputs!$B$35,0)) -> 0 | H21: =IF(Inputs!$B$49="Yes",0,IF(A21=Inputs!$B$30,G21*Inputs!$B$31,0)) -> 0 | I21: =IF(Inputs!$B$49="Yes",0,IF(A21=Inputs!$B$30,MAX(0,H21-F21),0)) -> 0 | J21: =IF(Inputs!$B$49="Yes",0,IF(A21=Inputs!$B$30,H21,F21)) -> 0
A22: 9 | B22: =IF(Inputs!$B$49="Yes",0,J21) -> 0 | C22: =IF(Inputs!$B$49="Yes",0,IF(A22<Inputs!$B$28,Inputs!$B$26/12*B22,PMT(Inputs!$B$26/12,Inputs!$B$27*12,-B22))) -> 0 | D22: =IF(Inputs!$B$49="Yes",0,B22*Inputs!$B$26/12) -> 0 | E22: =IF(Inputs!$B$49="Yes",0,MAX(0,C22-D22)) -> 0 | F22: =IF(Inputs!$B$49="Yes",0,MAX(0,B22-E22)) -> 0 | G22: =IF(Inputs!$B$49="Yes",0,IF(A22=Inputs!$B$30,('Operating Expenses'!D17*4)/Inputs!$B$35,0)) -> 0 | H22: =IF(Inputs!$B$49="Yes",0,IF(A22=Inputs!$B$30,G22*Inputs!$B$31,0)) -> 0 | I22: =IF(Inputs!$B$49="Yes",0,IF(A22=Inputs!$B$30,MAX(0,H22-F22),0)) -> 0 | J22: =IF(Inputs!$B$49="Yes",0,IF(A22=Inputs!$B$30,H22,F22)) -> 0
A23: 10 | B23: =IF(Inputs!$B$49="Yes",0,J22) -> 0 | C23: =IF(Inputs!$B$49="Yes",0,IF(A23<Inputs!$B$28,Inputs!$B$26/12*B23,PMT(Inputs!$B$26/12,Inputs!$B$27*12,-B23))) -> 0 | D23: =IF(Inputs!$B$49="Yes",0,B23*Inputs!$B$26/12) -> 0 | E23: =IF(Inputs!$B$49="Yes",0,MAX(0,C23-D23)) -> 0 | F23: =IF(Inputs!$B$49="Yes",0,MAX(0,B23-E23)) -> 0 | G23: =IF(Inputs!$B$49="Yes",0,IF(A23=Inputs!$B$30,('Operating Expenses'!D17*4)/Inputs!$B$35,0)) -> 0 | H23: =IF(Inputs!$B$49="Yes",0,IF(A23=Inputs!$B$30,G23*Inputs!$B$31,0)) -> 0 | I23: =IF(Inputs!$B$49="Yes",0,IF(A23=Inputs!$B$30,MAX(0,H23-F23),0)) -> 0 | J23: =IF(Inputs!$B$49="Yes",0,IF(A23=Inputs!$B$30,H23,F23)) -> 0
A24: 11 | B24: =IF(Inputs!$B$49="Yes",0,J23) -> 0 | C24: =IF(Inputs!$B$49="Yes",0,IF(A24<Inputs!$B$28,Inputs!$B$26/12*B24,PMT(Inputs!$B$26/12,Inputs!$B$27*12,-B24))) -> 0 | D24: =IF(Inputs!$B$49="Yes",0,B24*Inputs!$B$26/12) -> 0 | E24: =IF(Inputs!$B$49="Yes",0,MAX(0,C24-D24)) -> 0 | F24: =IF(Inputs!$B$49="Yes",0,MAX(0,B24-E24)) -> 0 | G24: =IF(Inputs!$B$49="Yes",0,IF(A24=Inputs!$B$30,('Operating Expenses'!D17*4)/Inputs!$B$35,0)) -> 0 | H24: =IF(Inputs!$B$49="Yes",0,IF(A24=Inputs!$B$30,G24*Inputs!$B$31,0)) -> 0 | I24: =IF(Inputs!$B$49="Yes",0,IF(A24=Inputs!$B$30,MAX(0,H24-F24),0)) -> 0 | J24: =IF(Inputs!$B$49="Yes",0,IF(A24=Inputs!$B$30,H24,F24)) -> 0
A25: 12 | B25: =IF(Inputs!$B$49="Yes",0,J24) -> 0 | C25: =IF(Inputs!$B$49="Yes",0,IF(A25<Inputs!$B$28,Inputs!$B$26/12*B25,PMT(Inputs!$B$26/12,Inputs!$B$27*12,-B25))) -> 0 | D25: =IF(Inputs!$B$49="Yes",0,B25*Inputs!$B$26/12) -> 0 | E25: =IF(Inputs!$B$49="Yes",0,MAX(0,C25-D25)) -> 0 | F25: =IF(Inputs!$B$49="Yes",0,MAX(0,B25-E25)) -> 0 | G25: =IF(Inputs!$B$49="Yes",0,IF(A25=Inputs!$B$30,('Operating Expenses'!D17*4)/Inputs!$B$35,0)) -> 0 | H25: =IF(Inputs!$B$49="Yes",0,IF(A25=Inputs!$B$30,G25*Inputs!$B$31,0)) -> 0 | I25: =IF(Inputs!$B$49="Yes",0,IF(A25=Inputs!$B$30,MAX(0,H25-F25),0)) -> 0 | J25: =IF(Inputs!$B$49="Yes",0,IF(A25=Inputs!$B$30,H25,F25)) -> 0
A26: 13 | B26: =IF(Inputs!$B$49="Yes",0,J25) -> 0 | C26: =IF(Inputs!$B$49="Yes",0,IF(A26<Inputs!$B$28,Inputs!$B$26/12*B26,PMT(Inputs!$B$26/12,Inputs!$B$27*12,-B26))) -> 0 | D26: =IF(Inputs!$B$49="Yes",0,B26*Inputs!$B$26/12) -> 0 | E26: =IF(Inputs!$B$49="Yes",0,MAX(0,C26-D26)) -> 0 | F26: =IF(Inputs!$B$49="Yes",0,MAX(0,B26-E26)) -> 0 | G26: =IF(Inputs!$B$49="Yes",0,IF(A26=Inputs!$B$30,('Operating Expenses'!D17*4)/Inputs!$B$35,0)) -> 0 | H26: =IF(Inputs!$B$49="Yes",0,IF(A26=Inputs!$B$30,G26*Inputs!$B$31,0)) -> 0 | I26: =IF(Inputs!$B$49="Yes",0,IF(A26=Inputs!$B$30,MAX(0,H26-F26),0)) -> 0 | J26: =IF(Inputs!$B$49="Yes",0,IF(A26=Inputs!$B$30,H26,F26)) -> 0
A27: 14 | B27: =IF(Inputs!$B$49="Yes",0,J26) -> 0 | C27: =IF(Inputs!$B$49="Yes",0,IF(A27<Inputs!$B$28,Inputs!$B$26/12*B27,PMT(Inputs!$B$26/12,Inputs!$B$27*12,-B27))) -> 0 | D27: =IF(Inputs!$B$49="Yes",0,B27*Inputs!$B$26/12) -> 0 | E27: =IF(Inputs!$B$49="Yes",0,MAX(0,C27-D27)) -> 0 | F27: =IF(Inputs!$B$49="Yes",0,MAX(0,B27-E27)) -> 0 | G27: =IF(Inputs!$B$49="Yes",0,IF(A27=Inputs!$B$30,('Operating Expenses'!D17*4)/Inputs!$B$35,0)) -> 0 | H27: =IF(Inputs!$B$49="Yes",0,IF(A27=Inputs!$B$30,G27*Inputs!$B$31,0)) -> 0 | I27: =IF(Inputs!$B$49="Yes",0,IF(A27=Inputs!$B$30,MAX(0,H27-F27),0)) -> 0 | J27: =IF(Inputs!$B$49="Yes",0,IF(A27=Inputs!$B$30,H27,F27)) -> 0
A28: 15 | B28: =IF(Inputs!$B$49="Yes",0,J27) -> 0 | C28: =IF(Inputs!$B$49="Yes",0,IF(A28<Inputs!$B$28,Inputs!$B$26/12*B28,PMT(Inputs!$B$26/12,Inputs!$B$27*12,-B28))) -> 0 | D28: =IF(Inputs!$B$49="Yes",0,B28*Inputs!$B$26/12) -> 0 | E28: =IF(Inputs!$B$49="Yes",0,MAX(0,C28-D28)) -> 0 | F28: =IF(Inputs!$B$49="Yes",0,MAX(0,B28-E28)) -> 0 | G28: =IF(Inputs!$B$49="Yes",0,IF(A28=Inputs!$B$30,('Operating Expenses'!D17*4)/Inputs!$B$35,0)) -> 0 | H28: =IF(Inputs!$B$49="Yes",0,IF(A28=Inputs!$B$30,G28*Inputs!$B$31,0)) -> 0 | I28: =IF(Inputs!$B$49="Yes",0,IF(A28=Inputs!$B$30,MAX(0,H28-F28),0)) -> 0 | J28: =IF(Inputs!$B$49="Yes",0,IF(A28=Inputs!$B$30,H28,F28)) -> 0
A29: 16 | B29: =IF(Inputs!$B$49="Yes",0,J28) -> 0 | C29: =IF(Inputs!$B$49="Yes",0,IF(A29<Inputs!$B$28,Inputs!$B$26/12*B29,PMT(Inputs!$B$26/12,Inputs!$B$27*12,-B29))) -> 0 | D29: =IF(Inputs!$B$49="Yes",0,B29*Inputs!$B$26/12) -> 0 | E29: =IF(Inputs!$B$49="Yes",0,MAX(0,C29-D29)) -> 0 | F29: =IF(Inputs!$B$49="Yes",0,MAX(0,B29-E29)) -> 0 | G29: =IF(Inputs!$B$49="Yes",0,IF(A29=Inputs!$B$30,('Operating Expenses'!D17*4)/Inputs!$B$35,0)) -> 0 | H29: =IF(Inputs!$B$49="Yes",0,IF(A29=Inputs!$B$30,G29*Inputs!$B$31,0)) -> 0 | I29: =IF(Inputs!$B$49="Yes",0,IF(A29=Inputs!$B$30,MAX(0,H29-F29),0)) -> 0 | J29: =IF(Inputs!$B$49="Yes",0,IF(A29=Inputs!$B$30,H29,F29)) -> 0
A30: 17 | B30: =IF(Inputs!$B$49="Yes",0,J29) -> 0 | C30: =IF(Inputs!$B$49="Yes",0,IF(A30<Inputs!$B$28,Inputs!$B$26/12*B30,PMT(Inputs!$B$26/12,Inputs!$B$27*12,-B30))) -> 0 | D30: =IF(Inputs!$B$49="Yes",0,B30*Inputs!$B$26/12) -> 0 | E30: =IF(Inputs!$B$49="Yes",0,MAX(0,C30-D30)) -> 0 | F30: =IF(Inputs!$B$49="Yes",0,MAX(0,B30-E30)) -> 0 | G30: =IF(Inputs!$B$49="Yes",0,IF(A30=Inputs!$B$30,('Operating Expenses'!D17*4)/Inputs!$B$35,0)) -> 0 | H30: =IF(Inputs!$B$49="Yes",0,IF(A30=Inputs!$B$30,G30*Inputs!$B$31,0)) -> 0 | I30: =IF(Inputs!$B$49="Yes",0,IF(A30=Inputs!$B$30,MAX(0,H30-F30),0)) -> 0 | J30: =IF(Inputs!$B$49="Yes",0,IF(A30=Inputs!$B$30,H30,F30)) -> 0
A31: 18 | B31: =IF(Inputs!$B$49="Yes",0,J30) -> 0 | C31: =IF(Inputs!$B$49="Yes",0,IF(A31<Inputs!$B$28,Inputs!$B$26/12*B31,PMT(Inputs!$B$26/12,Inputs!$B$27*12,-B31))) -> 0 | D31: =IF(Inputs!$B$49="Yes",0,B31*Inputs!$B$26/12) -> 0 | E31: =IF(Inputs!$B$49="Yes",0,MAX(0,C31-D31)) -> 0 | F31: =IF(Inputs!$B$49="Yes",0,MAX(0,B31-E31)) -> 0 | G31: =IF(Inputs!$B$49="Yes",0,IF(A31=Inputs!$B$30,('Operating Expenses'!D17*4)/Inputs!$B$35,0)) -> 0 | H31: =IF(Inputs!$B$49="Yes",0,IF(A31=Inputs!$B$30,G31*Inputs!$B$31,0)) -> 0 | I31: =IF(Inputs!$B$49="Yes",0,IF(A31=Inputs!$B$30,MAX(0,H31-F31),0)) -> 0 | J31: =IF(Inputs!$B$49="Yes",0,IF(A31=Inputs!$B$30,H31,F31)) -> 0
A32: 19 | B32: =IF(Inputs!$B$49="Yes",0,J31) -> 0 | C32: =IF(Inputs!$B$49="Yes",0,IF(A32<Inputs!$B$28,Inputs!$B$26/12*B32,PMT(Inputs!$B$26/12,Inputs!$B$27*12,-B32))) -> 0 | D32: =IF(Inputs!$B$49="Yes",0,B32*Inputs!$B$26/12) -> 0 | E32: =IF(Inputs!$B$49="Yes",0,MAX(0,C32-D32)) -> 0 | F32: =IF(Inputs!$B$49="Yes",0,MAX(0,B32-E32)) -> 0 | G32: =IF(Inputs!$B$49="Yes",0,IF(A32=Inputs!$B$30,('Operating Expenses'!D17*4)/Inputs!$B$35,0)) -> 0 | H32: =IF(Inputs!$B$49="Yes",0,IF(A32=Inputs!$B$30,G32*Inputs!$B$31,0)) -> 0 | I32: =IF(Inputs!$B$49="Yes",0,IF(A32=Inputs!$B$30,MAX(0,H32-F32),0)) -> 0 | J32: =IF(Inputs!$B$49="Yes",0,IF(A32=Inputs!$B$30,H32,F32)) -> 0
A33: 20 | B33: =IF(Inputs!$B$49="Yes",0,J32) -> 0 | C33: =IF(Inputs!$B$49="Yes",0,IF(A33<Inputs!$B$28,Inputs!$B$26/12*B33,PMT(Inputs!$B$26/12,Inputs!$B$27*12,-B33))) -> 0 | D33: =IF(Inputs!$B$49="Yes",0,B33*Inputs!$B$26/12) -> 0 | E33: =IF(Inputs!$B$49="Yes",0,MAX(0,C33-D33)) -> 0 | F33: =IF(Inputs!$B$49="Yes",0,MAX(0,B33-E33)) -> 0 | G33: =IF(Inputs!$B$49="Yes",0,IF(A33=Inputs!$B$30,('Operating Expenses'!D17*4)/Inputs!$B$35,0)) -> 0 | H33: =IF(Inputs!$B$49="Yes",0,IF(A33=Inputs!$B$30,G33*Inputs!$B$31,0)) -> 0 | I33: =IF(Inputs!$B$49="Yes",0,IF(A33=Inputs!$B$30,MAX(0,H33-F33),0)) -> 0 | J33: =IF(Inputs!$B$49="Yes",0,IF(A33=Inputs!$B$30,H33,F33)) -> 0
A34: 21 | B34: =IF(Inputs!$B$49="Yes",0,J33) -> 0 | C34: =IF(Inputs!$B$49="Yes",0,IF(A34<Inputs!$B$28,Inputs!$B$26/12*B34,PMT(Inputs!$B$26/12,Inputs!$B$27*12,-B34))) -> 0 | D34: =IF(Inputs!$B$49="Yes",0,B34*Inputs!$B$26/12) -> 0 | E34: =IF(Inputs!$B$49="Yes",0,MAX(0,C34-D34)) -> 0 | F34: =IF(Inputs!$B$49="Yes",0,MAX(0,B34-E34)) -> 0 | G34: =IF(Inputs!$B$49="Yes",0,IF(A34=Inputs!$B$30,('Operating Expenses'!D17*4)/Inputs!$B$35,0)) -> 0 | H34: =IF(Inputs!$B$49="Yes",0,IF(A34=Inputs!$B$30,G34*Inputs!$B$31,0)) -> 0 | I34: =IF(Inputs!$B$49="Yes",0,IF(A34=Inputs!$B$30,MAX(0,H34-F34),0)) -> 0 | J34: =IF(Inputs!$B$49="Yes",0,IF(A34=Inputs!$B$30,H34,F34)) -> 0
A35: 22 | B35: =IF(Inputs!$B$49="Yes",0,J34) -> 0 | C35: =IF(Inputs!$B$49="Yes",0,IF(A35<Inputs!$B$28,Inputs!$B$26/12*B35,PMT(Inputs!$B$26/12,Inputs!$B$27*12,-B35))) -> 0 | D35: =IF(Inputs!$B$49="Yes",0,B35*Inputs!$B$26/12) -> 0 | E35: =IF(Inputs!$B$49="Yes",0,MAX(0,C35-D35)) -> 0 | F35: =IF(Inputs!$B$49="Yes",0,MAX(0,B35-E35)) -> 0 | G35: =IF(Inputs!$B$49="Yes",0,IF(A35=Inputs!$B$30,('Operating Expenses'!D17*4)/Inputs!$B$35,0)) -> 0 | H35: =IF(Inputs!$B$49="Yes",0,IF(A35=Inputs!$B$30,G35*Inputs!$B$31,0)) -> 0 | I35: =IF(Inputs!$B$49="Yes",0,IF(A35=Inputs!$B$30,MAX(0,H35-F35),0)) -> 0 | J35: =IF(Inputs!$B$49="Yes",0,IF(A35=Inputs!$B$30,H35,F35)) -> 0
A36: 23 | B36: =IF(Inputs!$B$49="Yes",0,J35) -> 0 | C36: =IF(Inputs!$B$49="Yes",0,IF(A36<Inputs!$B$28,Inputs!$B$26/12*B36,PMT(Inputs!$B$26/12,Inputs!$B$27*12,-B36))) -> 0 | D36: =IF(Inputs!$B$49="Yes",0,B36*Inputs!$B$26/12) -> 0 | E36: =IF(Inputs!$B$49="Yes",0,MAX(0,C36-D36)) -> 0 | F36: =IF(Inputs!$B$49="Yes",0,MAX(0,B36-E36)) -> 0 | G36: =IF(Inputs!$B$49="Yes",0,IF(A36=Inputs!$B$30,('Operating Expenses'!D17*4)/Inputs!$B$35,0)) -> 0 | H36: =IF(Inputs!$B$49="Yes",0,IF(A36=Inputs!$B$30,G36*Inputs!$B$31,0)) -> 0 | I36: =IF(Inputs!$B$49="Yes",0,IF(A36=Inputs!$B$30,MAX(0,H36-F36),0)) -> 0 | J36: =IF(Inputs!$B$49="Yes",0,IF(A36=Inputs!$B$30,H36,F36)) -> 0
A37: 24 | B37: =IF(Inputs!$B$49="Yes",0,J36) -> 0 | C37: =IF(Inputs!$B$49="Yes",0,IF(A37<Inputs!$B$28,Inputs!$B$26/12*B37,PMT(Inputs!$B$26/12,Inputs!$B$27*12,-B37))) -> 0 | D37: =IF(Inputs!$B$49="Yes",0,B37*Inputs!$B$26/12) -> 0 | E37: =IF(Inputs!$B$49="Yes",0,MAX(0,C37-D37)) -> 0 | F37: =IF(Inputs!$B$49="Yes",0,MAX(0,B37-E37)) -> 0 | G37: =IF(Inputs!$B$49="Yes",0,IF(A37=Inputs!$B$30,('Operating Expenses'!D17*4)/Inputs!$B$35,0)) -> 0 | H37: =IF(Inputs!$B$49="Yes",0,IF(A37=Inputs!$B$30,G37*Inputs!$B$31,0)) -> 0 | I37: =IF(Inputs!$B$49="Yes",0,IF(A37=Inputs!$B$30,MAX(0,H37-F37),0)) -> 0 | J37: =IF(Inputs!$B$49="Yes",0,IF(A37=Inputs!$B$30,H37,F37)) -> 0
A38: 25 | B38: =IF(Inputs!$B$49="Yes",0,J37) -> 0 | C38: =IF(Inputs!$B$49="Yes",0,IF(A38<Inputs!$B$28,Inputs!$B$26/12*B38,PMT(Inputs!$B$26/12,Inputs!$B$27*12,-B38))) -> 0 | D38: =IF(Inputs!$B$49="Yes",0,B38*Inputs!$B$26/12) -> 0 | E38: =IF(Inputs!$B$49="Yes",0,MAX(0,C38-D38)) -> 0 | F38: =IF(Inputs!$B$49="Yes",0,MAX(0,B38-E38)) -> 0 | G38: =IF(Inputs!$B$49="Yes",0,IF(A38=Inputs!$B$30,('Operating Expenses'!D17*4)/Inputs!$B$35,0)) -> 0 | H38: =IF(Inputs!$B$49="Yes",0,IF(A38=Inputs!$B$30,G38*Inputs!$B$31,0)) -> 0 | I38: =IF(Inputs!$B$49="Yes",0,IF(A38=Inputs!$B$30,MAX(0,H38-F38),0)) -> 0 | J38: =IF(Inputs!$B$49="Yes",0,IF(A38=Inputs!$B$30,H38,F38)) -> 0
A39: 26 | B39: =IF(Inputs!$B$49="Yes",0,J38) -> 0 | C39: =IF(Inputs!$B$49="Yes",0,IF(A39<Inputs!$B$28,Inputs!$B$26/12*B39,PMT(Inputs!$B$26/12,Inputs!$B$27*12,-B39))) -> 0 | D39: =IF(Inputs!$B$49="Yes",0,B39*Inputs!$B$26/12) -> 0 | E39: =IF(Inputs!$B$49="Yes",0,MAX(0,C39-D39)) -> 0 | F39: =IF(Inputs!$B$49="Yes",0,MAX(0,B39-E39)) -> 0 | G39: =IF(Inputs!$B$49="Yes",0,IF(A39=Inputs!$B$30,('Operating Expenses'!D17*4)/Inputs!$B$35,0)) -> 0 | H39: =IF(Inputs!$B$49="Yes",0,IF(A39=Inputs!$B$30,G39*Inputs!$B$31,0)) -> 0 | I39: =IF(Inputs!$B$49="Yes",0,IF(A39=Inputs!$B$30,MAX(0,H39-F39),0)) -> 0 | J39: =IF(Inputs!$B$49="Yes",0,IF(A39=Inputs!$B$30,H39,F39)) -> 0
A40: 27 | B40: =IF(Inputs!$B$49="Yes",0,J39) -> 0 | C40: =IF(Inputs!$B$49="Yes",0,IF(A40<Inputs!$B$28,Inputs!$B$26/12*B40,PMT(Inputs!$B$26/12,Inputs!$B$27*12,-B40))) -> 0 | D40: =IF(Inputs!$B$49="Yes",0,B40*Inputs!$B$26/12) -> 0 | E40: =IF(Inputs!$B$49="Yes",0,MAX(0,C40-D40)) -> 0 | F40: =IF(Inputs!$B$49="Yes",0,MAX(0,B40-E40)) -> 0 | G40: =IF(Inputs!$B$49="Yes",0,IF(A40=Inputs!$B$30,('Operating Expenses'!D17*4)/Inputs!$B$35,0)) -> 0 | H40: =IF(Inputs!$B$49="Yes",0,IF(A40=Inputs!$B$30,G40*Inputs!$B$31,0)) -> 0 | I40: =IF(Inputs!$B$49="Yes",0,IF(A40=Inputs!$B$30,MAX(0,H40-F40),0)) -> 0 | J40: =IF(Inputs!$B$49="Yes",0,IF(A40=Inputs!$B$30,H40,F40)) -> 0
A41: 28 | B41: =IF(Inputs!$B$49="Yes",0,J40) -> 0 | C41: =IF(Inputs!$B$49="Yes",0,IF(A41<Inputs!$B$28,Inputs!$B$26/12*B41,PMT(Inputs!$B$26/12,Inputs!$B$27*12,-B41))) -> 0 | D41: =IF(Inputs!$B$49="Yes",0,B41*Inputs!$B$26/12) -> 0 | E41: =IF(Inputs!$B$49="Yes",0,MAX(0,C41-D41)) -> 0 | F41: =IF(Inputs!$B$49="Yes",0,MAX(0,B41-E41)) -> 0 | G41: =IF(Inputs!$B$49="Yes",0,IF(A41=Inputs!$B$30,('Operating Expenses'!D17*4)/Inputs!$B$35,0)) -> 0 | H41: =IF(Inputs!$B$49="Yes",0,IF(A41=Inputs!$B$30,G41*Inputs!$B$31,0)) -> 0 | I41: =IF(Inputs!$B$49="Yes",0,IF(A41=Inputs!$B$30,MAX(0,H41-F41),0)) -> 0 | J41: =IF(Inputs!$B$49="Yes",0,IF(A41=Inputs!$B$30,H41,F41)) -> 0
A42: 29 | B42: =IF(Inputs!$B$49="Yes",0,J41) -> 0 | C42: =IF(Inputs!$B$49="Yes",0,IF(A42<Inputs!$B$28,Inputs!$B$26/12*B42,PMT(Inputs!$B$26/12,Inputs!$B$27*12,-B42))) -> 0 | D42: =IF(Inputs!$B$49="Yes",0,B42*Inputs!$B$26/12) -> 0 | E42: =IF(Inputs!$B$49="Yes",0,MAX(0,C42-D42)) -> 0 | F42: =IF(Inputs!$B$49="Yes",0,MAX(0,B42-E42)) -> 0 | G42: =IF(Inputs!$B$49="Yes",0,IF(A42=Inputs!$B$30,('Operating Expenses'!D17*4)/Inputs!$B$35,0)) -> 0 | H42: =IF(Inputs!$B$49="Yes",0,IF(A42=Inputs!$B$30,G42*Inputs!$B$31,0)) -> 0 | I42: =IF(Inputs!$B$49="Yes",0,IF(A42=Inputs!$B$30,MAX(0,H42-F42),0)) -> 0 | J42: =IF(Inputs!$B$49="Yes",0,IF(A42=Inputs!$B$30,H42,F42)) -> 0
A43: 30 | B43: =IF(Inputs!$B$49="Yes",0,J42) -> 0 | C43: =IF(Inputs!$B$49="Yes",0,IF(A43<Inputs!$B$28,Inputs!$B$26/12*B43,PMT(Inputs!$B$26/12,Inputs!$B$27*12,-B43))) -> 0 | D43: =IF(Inputs!$B$49="Yes",0,B43*Inputs!$B$26/12) -> 0 | E43: =IF(Inputs!$B$49="Yes",0,MAX(0,C43-D43)) -> 0 | F43: =IF(Inputs!$B$49="Yes",0,MAX(0,B43-E43)) -> 0 | G43: =IF(Inputs!$B$49="Yes",0,IF(A43=Inputs!$B$30,('Operating Expenses'!D17*4)/Inputs!$B$35,0)) -> 0 | H43: =IF(Inputs!$B$49="Yes",0,IF(A43=Inputs!$B$30,G43*Inputs!$B$31,0)) -> 0 | I43: =IF(Inputs!$B$49="Yes",0,IF(A43=Inputs!$B$30,MAX(0,H43-F43),0)) -> 0 | J43: =IF(Inputs!$B$49="Yes",0,IF(A43=Inputs!$B$30,H43,F43)) -> 0
...

Sheet Fees
A1: Sponsor Fee Module
A3: Year | B3: EGI | C3: Acquisition Fee | D3: Asset Management Fee | E3: Disposition Fee | F3: Total Sponsor Fees
A4: 0 | B4: 0 | C4: =Inputs!B4*Inputs!B7 -> 85000 | D4: 0 | E4: 0 | F4: =SUM(C4:E4) -> 85000
A5: 1 | B5: ='Revenue Forecast'!F4 -> 1064309.1 | C5: 0 | D5: =B5*Inputs!$B$8 -> 15964.637 | E5: =IF(A5=Inputs!$B$35/12,'Returns Summary'!B15*Inputs!$B$9,0) -> 0 | F5: =SUM(C5:E5) -> 15964.637
A6: 2 | B6: ='Revenue Forecast'!F5 -> 1285590.5 | C6: 0 | D6: =B6*Inputs!$B$8 -> 19283.857 | E6: =IF(A6=Inputs!$B$35/12,'Returns Summary'!B15*Inputs!$B$9,0) -> 0 | F6: =SUM(C6:E6) -> 19283.857
A7: 3 | B7: ='Revenue Forecast'!F6 -> 1494168.5 | C7: 0 | D7: =B7*Inputs!$B$8 -> 22412.527 | E7: =IF(A7=Inputs!$B$35/12,'Returns Summary'!B15*Inputs!$B$9,0) -> 0 | F7: =SUM(C7:E7) -> 22412.527
A8: 4 | B8: ='Revenue Forecast'!F7 -> 1713038.7 | C8: 0 | D8: =B8*Inputs!$B$8 -> 25695.581 | E8: =IF(A8=Inputs!$B$35/12,'Returns Summary'!B15*Inputs!$B$9,0) -> 0 | F8: =SUM(C8:E8) -> 25695.581
A9: 5 | B9: ='Revenue Forecast'!F8 -> 1784969 | C9: 0 | D9: =B9*Inputs!$B$8 -> 26774.535 | E9: =IF(A9=Inputs!$B$35/12,'Returns Summary'!B15*Inputs!$B$9,0) -> 0 | F9: =SUM(C9:E9) -> 26774.535

Sheet GP-LP Waterfall
A1: GP / LP Waterfall with Promote - Tiered Structure
A3: Equity Contributions
A4: Total Equity Required | B4: ='Returns Summary'!B14 -> 4612500
A5: GP Co-Invest | B5: =B4*Inputs!B10 -> 0
A6: LP Equity | B6: =B4-B5 -> 4612500
A9: Year | B9: Distributable CF | C9: Return of Capital 100% LP | D9: Preferred Return 8% | E9: Remaining CF | F9: Catch-Up LP 80% | G9: Catch-Up GP 20% | H9: Residual LP 80% | I9: Residual GP 20% | J9: LP Total | K9: GP Total
A10: 1 | B10: ='Returns Summary'!I6 -> 510129.02 | C10: =MIN(B10,MAX(0,$B$6-0)) -> 510129.02 | D10: =MIN(MAX(0,B10-C10),$B$6*Inputs!$B$40) -> 0 | E10: =MAX(0,B10-C10-D10) -> 0 | F10: =MIN(E10,$B$6*Inputs!$B$40)*Inputs!$B$42 -> 0 | G10: =MIN(E10,$B$6*Inputs!$B$40)*Inputs!$B$43 -> 0 | H10: =MAX(0,E10-F10-G10)*Inputs!$B$45 -> 0 | I10: =MAX(0,E10-F10-G10)*Inputs!$B$46 -> 0 | J10: =C10+D10+F10+H10 -> 510129.02 | K10: =G10+I10 -> 0
A11: 2 | B11: ='Returns Summary'!I7 -> 714635.76 | C11: =MIN(B11,MAX(0,$B$6-SUM($C$10:C10))) -> 714635.76 | D11: =MIN(MAX(0,B11-C11),$B$6*Inputs!$B$40) -> 0 | E11: =MAX(0,B11-C11-D11) -> 0 | F11: =MIN(E11,$B$6*Inputs!$B$40)*Inputs!$B$42 -> 0 | G11: =MIN(E11,$B$6*Inputs!$B$40)*Inputs!$B$43 -> 0 | H11: =MAX(0,E11-F11-G11)*Inputs!$B$45 -> 0 | I11: =MAX(0,E11-F11-G11)*Inputs!$B$46 -> 0 | J11: =C11+D11+F11+H11 -> 714635.76 | K11: =G11+I11 -> 0
A12: 3 | B12: ='Returns Summary'!I8 -> 988875.81 | C12: =MIN(B12,MAX(0,$B$6-SUM($C$10:C11))) -> 988875.81 | D12: =MIN(MAX(0,B12-C12),$B$6*Inputs!$B$40) -> 0 | E12: =MAX(0,B12-C12-D12) -> 0 | F12: =MIN(E12,$B$6*Inputs!$B$40)*Inputs!$B$42 -> 0 | G12: =MIN(E12,$B$6*Inputs!$B$40)*Inputs!$B$43 -> 0 | H12: =MAX(0,E12-F12-G12)*Inputs!$B$45 -> 0 | I12: =MAX(0,E12-F12-G12)*Inputs!$B$46 -> 0 | J12: =C12+D12+F12+H12 -> 988875.81 | K12: =G12+I12 -> 0
A13: 4 | B13: ='Returns Summary'!I9 -> 1287924 | C13: =MIN(B13,MAX(0,$B$6-SUM($C$10:C12))) -> 1287924 | D13: =MIN(MAX(0,B13-C13),$B$6*Inputs!$B$40) -> 0 | E13: =MAX(0,B13-C13-D13) -> 0 | F13: =MIN(E13,$B$6*Inputs!$B$40)*Inputs!$B$42 -> 0 | G13: =MIN(E13,$B$6*Inputs!$B$40)*Inputs!$B$43 -> 0 | H13: =MAX(0,E13-F13-G13)*Inputs!$B$45 -> 0 | I13: =MAX(0,E13-F13-G13)*Inputs!$B$46 -> 0 | J13: =C13+D13+F13+H13 -> 1287924 | K13: =G13+I13 -> 0
A14: 5 | B14: ='Returns Summary'!I10 -> 17441696 | C14: =MIN(B14,MAX(0,$B$6-SUM($C$10:C13))) -> 1110935.5 | D14: =MIN(MAX(0,B14-C14),$B$6*Inputs!$B$40) -> 369000 | E14: =MAX(0,B14-C14-D14) -> 15961760 | F14: =MIN(E14,$B$6*Inputs!$B$40)*Inputs!$B$42 -> 295200 | G14: =MIN(E14,$B$6*Inputs!$B$40)*Inputs!$B$43 -> 73800 | H14: =MAX(0,E14-F14-G14)*Inputs!$B$45 -> 12474208 | I14: =MAX(0,E14-F14-G14)*Inputs!$B$46 -> 3118552 | J14: =C14+D14+F14+H14 -> 14249344 | K14: =G14+I14 -> 3192352
A17: Waterfall Summary
A18: LP Total Distributions | B18: =SUM(J10:J14) -> 17750908 | D18: LP CF | E18: GP CF
A19: GP Total Distributions | B19: =SUM(K10:K14) -> 3192352 | D19: =-$B$6 -> -4612500 | E19: =-$B$5 -> 0
A20: LP Equity Multiple | B20: =IFERROR(B18/B6,"N/A") -> 3.8484354 | D20: =J10 -> 510129.02 | E20: =K10 -> 0
A21: GP Equity Multiple | B21: =IFERROR(B19/B5,"N/A") -> N/A | D21: =J11 -> 714635.76 | E21: =K11 -> 0
A22: LP IRR | B22: =IFERROR(IRR(D19:D24),"N/A") -> 0.35867055 | D22: =J12 -> 988875.81 | E22: =K12 -> 0
A23: GP IRR | B23: =IFERROR(IRR(E19:E24),"N/A") -> N/A | D23: =J13 -> 1287924 | E23: =K13 -> 0
A24: Total MOIC | B24: =IFERROR((B18+B19)/B4,"N/A") -> 4.5405442 | D24: =J14 -> 14249344 | E24: =K14 -> 3192352

Sheet Returns Summary
A1: Returns Summary / Cash Flow Model
A4: Year | B4: NOI | C4: Expansion NOI | D4: Debt Service | E4: Refi Proceeds | F4: Sponsor Fees | G4: Net Cash Flow Before Sale | H4: Sale Proceeds | I4: Total Cash Flow
A5: 0 | I5: =-'Debt & Refi'!B6 -> -4612500
A6: 1 | B6: ='Operating Expenses'!B17 -> 526093.66 | C6: =SUM('Expansion CapEx'!F17:F28) -> 0 | D6: =SUM('Debt & Refi'!C14:C25) -> 0 | E6: =SUM('Debt & Refi'!I14:I25) -> 0 | F6: =Fees!F5 -> 15964.637 | G6: =B6+C6-D6+E6-F6 -> 510129.02 | H6: =IF(A6=Inputs!$B$36/12,MAX(0,B6/Inputs!$B$35*(1-Inputs!$B$37)-'Debt & Refi'!J73),0) -> 0 | I6: =G6+H6 -> 510129.02
A7: 2 | B7: ='Operating Expenses'!C17 -> 733919.61 | C7: =SUM('Expansion CapEx'!F29:F40) -> 0 | D7: =SUM('Debt & Refi'!C26:C37) -> 0 | E7: =SUM('Debt & Refi'!I26:I37) -> 0 | F7: =Fees!F6 -> 19283.857 | G7: =B7+C7-D7+E7-F7 -> 714635.76 | H7: =IF(A7=Inputs!$B$36/12,MAX(0,B7/Inputs!$B$35*(1-Inputs!$B$37)-'Debt & Refi'!J73),0) -> 0 | I7: =G7+H7 -> 714635.76
A8: 3 | B8: ='Operating Expenses'!D17 -> 928705.84 | C8: =SUM('Expansion CapEx'!F41:F52) -> 82582.5 | D8: =SUM('Debt & Refi'!C38:C49) -> 0 | E8: =SUM('Debt & Refi'!I38:I49) -> 0 | F8: =Fees!F7 -> 22412.527 | G8: =B8+C8-D8+E8-F8 -> 988875.81 | H8: =IF(A8=Inputs!$B$36/12,MAX(0,B8/Inputs!$B$35*(1-Inputs!$B$37)-'Debt & Refi'!J73),0) -> 0 | I8: =G8+H8 -> 988875.81
A9: 4 | B9: ='Operating Expenses'!E17 -> 1133439.5 | C9: =SUM('Expansion CapEx'!F53:F64) -> 180180 | D9: =SUM('Debt & Refi'!C50:C61) -> 0 | E9: =SUM('Debt & Refi'!I50:I61) -> 0 | F9: =Fees!F8 -> 25695.581 | G9: =B9+C9-D9+E9-F9 -> 1287924 | H9: =IF(A9=Inputs!$B$36/12,MAX(0,B9/Inputs!$B$35*(1-Inputs!$B$37)-'Debt & Refi'!J73),0) -> 0 | I9: =G9+H9 -> 1287924
A10: 5 | B10: ='Operating Expenses'!F17 -> 1190879.8 | C10: =SUM('Expansion CapEx'!F65:F76) -> 180180 | D10: =SUM('Debt & Refi'!C62:C73) -> 0 | E10: =SUM('Debt & Refi'!I62:I73) -> 0 | F10: =Fees!F9 -> 26774.535 | G10: =B10+C10-D10+E10-F10 -> 1344285.3 | H10: =IF(A10=Inputs!$B$36/12,MAX(0,B10/Inputs!$B$35*(1-Inputs!$B$37)-'Debt & Refi'!J73),0) -> 16097410 | I10: =G10+H10 -> 17441696
A13: Return Metrics
A14: Total Equity | B14: =-I5 -> 4612500
A15: Exit Value | B15: =B10/Inputs!B35 -> 16425929
A16: Levered IRR | B16: =IRR(I5:I10) -> 0.40394317
A17: Equity Multiple | B17: =SUM(I6:I10)/ABS(I5) -> 4.5405442
A18: Avg Cash-on-Cash | B18: =AVERAGE(G6:G10)/ABS(I5) -> 0.21011815
A19: Year 1 DSCR | B19: =IF(Inputs!$B$49="Yes","N/A",IFERROR('Operating Expenses'!B17/'Debt & Refi'!B7,"N/A")) -> N/A
A20: Year 1 Debt Yield | B20: =IF(Inputs!$B$49="Yes","N/A",IFERROR('Operating Expenses'!B17/'Debt & Refi'!B5,"N/A")) -> N/A
A22: Unlevered Metrics
A23: Unlevered IRR | B23: ='Unlevered Scenarios'!B22 -> 0.14687227
A24: Unlevered Equity Multiple | B24: ='Unlevered Scenarios'!B23 -> 1.8700096
A25: Unlevered Avg Cash-on-Cash | B25: ='Unlevered Scenarios'!B24 -> 0.08007639
A26: Unlevered Exit Value | B26: ='Unlevered Scenarios'!B25 -> 15534422
A27: Unlevered Net Sale Proceeds | B27: ='Unlevered Scenarios'!B26 -> 15223733
A28: Unlevered Y5 NOI Yield on Cost | B28: ='Unlevered Scenarios'!B27 -> 0.10575076
A29: Active Scenario | B29: Base / Current
A31: Expanded Return Metrics
A32: LP Equity Multiple | B32: ='GP-LP Waterfall'!B20 -> 3.8484354
A33: GP Equity Multiple | B33: ='GP-LP Waterfall'!B21 -> N/A
A34: MOIC | B34: =B17 -> 4.5405442
A35: Yield on Cost | B35: =B10/'Debt & Refi'!B4 -> 0.25818533
A36: Exit Yield | B36: =B10/B15 -> 0.0725
A38: Acquisition Diagnostics
A39: Price per Rentable SF | B39: =IFERROR(Inputs!B4/('Unit Mix & Market Comps'!B11*'Unit Mix & Market Comps'!C11),"N/A") -> 89.005236
A40: Price per Unit | B40: =IFERROR(Inputs!B4/'Unit Mix & Market Comps'!B11,"N/A") -> 8415.8416
A41: Going-In Cap | B41: =IFERROR('Operating Expenses'!B17/Inputs!B4,"N/A") -> 0.12378674
A42: Stabilized Cap | B42: =IFERROR('Operating Expenses'!F17/Inputs!B4,"N/A") -> 0.28020702
A43: Total Cost per Rentable SF | B43: =IFERROR('Debt & Refi'!B4/('Unit Mix & Market Comps'!B11*'Unit Mix & Market Comps'!C11),"N/A") -> 96.596859
A44: Total Cost per Unit | B44: =IFERROR('Debt & Refi'!B4/'Unit Mix & Market Comps'!B11,"N/A") -> 9133.6634
A46: Debt Mode | B46: =Inputs!B50 -> Levered
A47: Unlevered Toggle | B47: =Inputs!B49 -> No

Sheet Sensitivity
A1: Sensitivity Tables
A3: Purchase Price / Exit Cap Sensitivity - Approx Levered IRR
A4: Exit Cap / Price | B4: 8000000 | C4: 9000000 | D4: 10000000 | E4: 11000000 | F4: 12000000
A5: 0.065 | B5: =((('Operating Expenses'!F17/B$4)*(1-$A5)+0.01)*5) -> 0.74592041 | C5: =((('Operating Expenses'!F17/C$4)*(1-$A5)+0.01)*5) -> 0.66859592 | D5: =((('Operating Expenses'!F17/D$4)*(1-$A5)+0.01)*5) -> 0.60673633 | E5: =((('Operating Expenses'!F17/E$4)*(1-$A5)+0.01)*5) -> 0.55612393 | F5: =((('Operating Expenses'!F17/F$4)*(1-$A5)+0.01)*5) -> 0.51394694
A6: 0.07 | B6: =((('Operating Expenses'!F17/B$4)*(1-$A6)+0.01)*5) -> 0.74219891 | C6: =((('Operating Expenses'!F17/C$4)*(1-$A6)+0.01)*5) -> 0.66528792 | D6: =((('Operating Expenses'!F17/D$4)*(1-$A6)+0.01)*5) -> 0.60375913 | E6: =((('Operating Expenses'!F17/E$4)*(1-$A6)+0.01)*5) -> 0.55341739 | F6: =((('Operating Expenses'!F17/F$4)*(1-$A6)+0.01)*5) -> 0.51146594
A7: 0.0725 | B7: =((('Operating Expenses'!F17/B$4)*(1-$A7)+0.01)*5) -> 0.74033816 | C7: =((('Operating Expenses'!F17/C$4)*(1-$A7)+0.01)*5) -> 0.66363392 | D7: =((('Operating Expenses'!F17/D$4)*(1-$A7)+0.01)*5) -> 0.60227053 | E7: =((('Operating Expenses'!F17/E$4)*(1-$A7)+0.01)*5) -> 0.55206412 | F7: =((('Operating Expenses'!F17/F$4)*(1-$A7)+0.01)*5) -> 0.51022544
A8: 0.075 | B8: =((('Operating Expenses'!F17/B$4)*(1-$A8)+0.01)*5) -> 0.73847741 | C8: =((('Operating Expenses'!F17/C$4)*(1-$A8)+0.01)*5) -> 0.66197992 | D8: =((('Operating Expenses'!F17/D$4)*(1-$A8)+0.01)*5) -> 0.60078193 | E8: =((('Operating Expenses'!F17/E$4)*(1-$A8)+0.01)*5) -> 0.55071084 | F8: =((('Operating Expenses'!F17/F$4)*(1-$A8)+0.01)*5) -> 0.50898494
A9: 0.08 | B9: =((('Operating Expenses'!F17/B$4)*(1-$A9)+0.01)*5) -> 0.73475591 | C9: =((('Operating Expenses'!F17/C$4)*(1-$A9)+0.01)*5) -> 0.65867192 | D9: =((('Operating Expenses'!F17/D$4)*(1-$A9)+0.01)*5) -> 0.59780473 | E9: =((('Operating Expenses'!F17/E$4)*(1-$A9)+0.01)*5) -> 0.5480043 | F9: =((('Operating Expenses'!F17/F$4)*(1-$A9)+0.01)*5) -> 0.50650394
A13: Occupancy / Rent Growth Sensitivity - Year 5 NOI
A14: Rent Growth / Occ | B14: 0.82 | C14: 0.86 | D14: 0.9 | E14: 0.92 | F14: 0.94
A15: 0.02 | B15: =('Unit Mix & Market Comps'!$H$11*(1+$A15)^5*B$14*(1-Inputs!$B$17)+Inputs!$B$21*12)-'Operating Expenses'!F15 -> 531359.9 | C15: =('Unit Mix & Market Comps'!$H$11*(1+$A15)^5*C$14*(1-Inputs!$B$17)+Inputs!$B$21*12)-'Operating Expenses'!F15 -> 584796.44 | D15: =('Unit Mix & Market Comps'!$H$11*(1+$A15)^5*D$14*(1-Inputs!$B$17)+Inputs!$B$21*12)-'Operating Expenses'!F15 -> 638232.98 | E15: =('Unit Mix & Market Comps'!$H$11*(1+$A15)^5*E$14*(1-Inputs!$B$17)+Inputs!$B$21*12)-'Operating Expenses'!F15 -> 664951.25 | F15: =('Unit Mix & Market Comps'!$H$11*(1+$A15)^5*F$14*(1-Inputs!$B$17)+Inputs!$B$21*12)-'Operating Expenses'!F15 -> 691669.52
A16: 0.03 | B16: =('Unit Mix & Market Comps'!$H$11*(1+$A16)^5*B$14*(1-Inputs!$B$17)+Inputs!$B$21*12)-'Operating Expenses'!F15 -> 586121.67 | C16: =('Unit Mix & Market Comps'!$H$11*(1+$A16)^5*C$14*(1-Inputs!$B$17)+Inputs!$B$21*12)-'Operating Expenses'!F15 -> 642229.51 | D16: =('Unit Mix & Market Comps'!$H$11*(1+$A16)^5*D$14*(1-Inputs!$B$17)+Inputs!$B$21*12)-'Operating Expenses'!F15 -> 698337.36 | E16: =('Unit Mix & Market Comps'!$H$11*(1+$A16)^5*E$14*(1-Inputs!$B$17)+Inputs!$B$21*12)-'Operating Expenses'!F15 -> 726391.28 | F16: =('Unit Mix & Market Comps'!$H$11*(1+$A16)^5*F$14*(1-Inputs!$B$17)+Inputs!$B$21*12)-'Operating Expenses'!F15 -> 754445.2
