Workbook

Sheet Inputs
A1: Global Inputs
A3: Acquisition / Fees
A4: Purchase Price | B4: 4250000
A5: Closing Costs % | B5: 0.03
A6: Initial Repairs / Deferred CapEx | B6: 150000
A7: Acquisition Fee % | B7: 0.02
A8: Asset Management Fee % of EGI | B8: 0.015
A9: Disposition Fee % | B9: 0.01
A10: Sponsor Co-Invest % of Equity | B10: 0
A12: Operations
A13: Start Physical Occupancy | B13: 0.707
A14: Stabilized Physical Occupancy | B14: 0.9
A15: Months to Stabilization | B15: 18
A16: Occupancy Curve Type | B16: Logistic
A17: Economic Occupancy Discount | B17: 0.03
A18: Annual Street Rent Growth | B18: 0.05
A19: Admin / Fees % of Rental Revenue | B19: 0.04
A20: Tenant Insurance Income % | B20: 0.05
A21: Other Income / Month | B21: 2500
A22: OpEx Growth | B22: 0.025
A25: Debt / Refi / Exit
A26: Initial LTV | B26: 0.45
A27: Initial Interest Rate | B27: 0.085
A28: Initial Amortization Years | B28: 30
A29: IO Period Months | B29: 24
A30: Minimum DSCR | B30: 1.25
A31: Refi Month | B31: 24
A32: Refi LTV | B32: 0.65
A33: Refi Interest Rate | B33: 0.0525
A34: Refi Amortization Years | B34: 30
A35: Exit Cap Rate | B35: 0.0725
A36: Exit Month | B36: 60
A37: Selling Costs % | B37: 0.02
A40: Preferred Return
A41: Return of Capital - LP | B41: 1
A42: Catch-Up Split - LP | B42: 0.8
A43: Catch-Up Split - GP | B43: 0.2
A44: Residual Hurdle / Reference | B44: 0.08
A45: Residual Split - LP | B45: 0.8
A46: Residual Split - GP | B46: 0.2
...

Sheet Dashboard
A1: Institutional Self-Storage Acquisition Dashboard
A3: Key Investment Metrics
A4: Purchase Price | B4: =Inputs!B4
A5: Total Project Cost | B5: ='Debt & Refi'!B4
A6: Equity Required | B6: ='Debt & Refi'!B6
A7: Year 1 NOI | B7: ='Operating Expenses'!B17
A8: Year 5 NOI | B8: ='Operating Expenses'!F17
A9: Levered IRR | B9: ='Returns Summary'!B16
A10: Equity Multiple | B10: ='Returns Summary'!B17
A11: Avg Cash-on-Cash | B11: ='Returns Summary'!B18
A12: Year 1 DSCR | B12: ='Returns Summary'!B19
A13: Year 1 Debt Yield | B13: ='Returns Summary'!B20
A14: Exit Value | B14: ='Returns Summary'!B15
A17: Flags / Credit Committee Checks
A18: DSCR Status | B18: =IF(ISNUMBER(B12),IF(B12>=Inputs!B29,"PASS","FAIL"),"N/A - Unlevered")
A19: Debt Yield Status | B19: =IF(ISNUMBER(B13),IF(B13>=8%,"PASS","WATCH"),"N/A - Unlevered")
A20: Exit Cap Spread | B20: =Inputs!B34-Inputs!B26
A21: Stabilized Occ. | B21: =Inputs!B14
A23: Unlevered Scenario Metrics
A24: Unlevered IRR | B24: ='Returns Summary'!B23
A25: Unlevered Equity Multiple | B25: ='Returns Summary'!B24
A26: Unlevered Avg Cash-on-Cash | B26: ='Returns Summary'!B25
A27: Unlevered Exit Value | B27: ='Returns Summary'!B26
A28: Unlevered Y5 NOI Yield on Cost | B28: ='Returns Summary'!B28
A30: Expanded Investor Metrics
A31: LP Equity Multiple | B31: ='Returns Summary'!B32
A32: GP Equity Multiple | B32: ='Returns Summary'!B33
A33: MOIC | B33: ='Returns Summary'!B34
A34: Yield on Cost | B34: ='Returns Summary'!B35
A35: Exit Yield | B35: ='Returns Summary'!B36
A37: Acquisition Diagnostics
A38: Price per Rentable SF | B38: ='Returns Summary'!B39
A39: Price per Unit | B39: ='Returns Summary'!B40
A40: Stabilized Cap | B40: ='Returns Summary'!B42
A41: Going-In Cap | B41: ='Returns Summary'!B41
A42: Debt Mode | B42: ='Returns Summary'!B46
A43: Unlevered Toggle | B43: Yes

Sheet Sources & Notes
A1: Sources & Notes / Model Guide
A3: Purpose | B3: Institutional self-storage acquisition model for lender and investor review.
A4: Replace inputs | B4: All blue/yellow cells are sample inputs and should be replaced with real rent roll, T-12, tax, insurance, debt, construction, and market comp data.
A5: Color convention | B5: Blue/yellow = editable input; green = linked from another worksheet; black = formula.
A6: Caution | B6: Waterfall is an annual simplified promote model and should be reviewed by counsel/CPA before investor use.
A9: Due Diligence Checklist
A10: Rent roll by unit type
A11: T-12 / T-3 P&L
A12: Physical and economic occupancy
A13: Rate history and street rates
A14: Delinquency / bad debt
A15: Tax bill and reassessment
A16: Insurance quote
A17: Debt term sheet
A18: Expansion zoning / permits
A19: Market comp survey URLs

Sheet Unit Mix & Market Comps
A1: Unit Mix & Market Rent Comp Integration
A3: Subject Unit Mix
A4: Unit Type | B4: Units | C4: Avg SF | D4: Current Rent / Mo. | E4: Market Rent / Mo. | F4: Premium / Discount | G4: Current Annual GPR | H4: Market Annual GPR
A5: 5x5 | B5: 100 | C5: 25 | D5: 80 | E5: 90 | F5: =IFERROR(E5/D5-1,0) | G5: =B5*D5*12 | H5: =B5*E5*12
A6: 5x10 | B6: 120 | C6: 50 | D6: 125 | E6: 135 | F6: =IFERROR(E6/D6-1,0) | G6: =B6*D6*12 | H6: =B6*E6*12
A7: 10x10 | B7: 140 | C7: 100 | D7: 205 | E7: 225 | F7: =IFERROR(E7/D7-1,0) | G7: =B7*D7*12 | H7: =B7*E7*12
A8: 10x15 | B8: 75 | C8: 150 | D8: 285 | E8: 310 | F8: =IFERROR(E8/D8-1,0) | G8: =B8*D8*12 | H8: =B8*E8*12
A9: 10x20 | B9: 50 | C9: 200 | D9: 375 | E9: 410 | F9: =IFERROR(E9/D9-1,0) | G9: =B9*D9*12 | H9: =B9*E9*12
A10: Parking / Outdoor | B10: 20 | C10: 200 | D10: 150 | E10: 175 | F10: =IFERROR(E10/D10-1,0) | G10: =B10*D10*12 | H10: =B10*E10*12
A11: Total / Weighted Avg | B11: =SUM(B5:B10) | C11: =SUMPRODUCT(B5:B10,C5:C10)/B11 | D11: =SUMPRODUCT(B5:B10,D5:D10)/B11 | E11: =SUMPRODUCT(B5:B10,E5:E10)/B11 | F11: =IFERROR(E11/D11-1,0) | G11: =SUM(G5:G10) | H11: =SUM(H5:H10)
A14: Market Rent Comps
A15: Comp Name | B15: Market / Address | C15: Distance | D15: Unit Type | E15: Quoted Rent / Mo. | F15: Source / URL | G15: Date | H15: Notes
A16: Comp 1 | D16: 10x10 | E16: 0 | F16: Add source URL
A17: Comp 2 | D17: 10x10 | E17: 0 | F17: Add source URL
A18: Comp 3 | D18: 10x10 | E18: 0 | F18: Add source URL
A19: Comp 4 | D19: 10x10 | E19: 0 | F19: Add source URL
A20: Comp 5 | D20: 10x10 | E20: 0 | F20: Add source URL
A21: Comp 6 | D21: 10x10 | E21: 0 | F21: Add source URL
A22: Comp 7 | D22: 10x10 | E22: 0 | F22: Add source URL
A23: Comp 8 | D23: 10x10 | E23: 0 | F23: Add source URL
A24: Comp 9 | D24: 10x10 | E24: 0 | F24: Add source URL
A25: Comp 10 | D25: 10x10 | E25: 0 | F25: Add source URL
A28: Comp Summary
A29: Average Quoted Rent / Mo. | B29: =IFERROR(AVERAGEIF(E16:E25,">0",E16:E25),"N/A")
A30: Subject Weighted Market Rent / Mo. | B30: =E11
A31: Subject vs Comp Rent | B31: =IFERROR(B30/B29-1,0)

Sheet Monthly Lease-Up
A1: Monthly Lease-Up / Dynamic Occupancy Curves
A3: Month | B3: Year | C3: Beginning Occ. | D3: Curve Occ. | E3: Physical Occ. | F3: Leased Units | G3: Economic Occ. | H3: Monthly Rent Growth | I3: Weighted Market Rent | J3: Rental Revenue | K3: Ancillary Income | L3: Total EGI
A4: 1 | B4: =ROUNDUP(A4/12,0) | C4: =Inputs!B13 | D4: =IF(Inputs!$B$16="Linear",MIN(Inputs!$B$14,Inputs!$B$13+(Inputs!$B$14-Inputs!$B$13)*A4/Inputs!$B$15),IF(Inputs!$B$16="S-Curve",Inputs!$B$13+(Inputs!$B$14-Inputs!$B$13)/(1+EXP(-0.25*(A4-Inputs!$B$15/2))),Inputs!$B$13+(Inputs!$B$14-Inputs!$B$13)/(1+EXP(-0.35*(A4-Inputs!$B$15/2))))) | E4: =MIN(Inputs!$B$14,D4) | F4: ='Unit Mix & Market Comps'!$B$11*E4 | G4: =MAX(0,E4-Inputs!$B$17) | H4: =Inputs!$B$18/12 | I4: ='Unit Mix & Market Comps'!$E$11*(1+H4)^(A4-1) | J4: ='Unit Mix & Market Comps'!$B$11*I4*G4 | K4: =J4*(Inputs!$B$19+Inputs!$B$20)+Inputs!$B$21 | L4: =J4+K4
A5: 2 | B5: =ROUNDUP(A5/12,0) | C5: =E4 | D5: =IF(Inputs!$B$16="Linear",MIN(Inputs!$B$14,Inputs!$B$13+(Inputs!$B$14-Inputs!$B$13)*A5/Inputs!$B$15),IF(Inputs!$B$16="S-Curve",Inputs!$B$13+(Inputs!$B$14-Inputs!$B$13)/(1+EXP(-0.25*(A5-Inputs!$B$15/2))),Inputs!$B$13+(Inputs!$B$14-Inputs!$B$13)/(1+EXP(-0.35*(A5-Inputs!$B$15/2))))) | E5: =MIN(Inputs!$B$14,D5) | F5: ='Unit Mix & Market Comps'!$B$11*E5 | G5: =MAX(0,E5-Inputs!$B$17) | H5: =Inputs!$B$18/12 | I5: ='Unit Mix & Market Comps'!$E$11*(1+H5)^(A5-1) | J5: ='Unit Mix & Market Comps'!$B$11*I5*G5 | K5: =J5*(Inputs!$B$19+Inputs!$B$20)+Inputs!$B$21 | L5: =J5+K5
A6: 3 | B6: =ROUNDUP(A6/12,0) | C6: =E5 | D6: =IF(Inputs!$B$16="Linear",MIN(Inputs!$B$14,Inputs!$B$13+(Inputs!$B$14-Inputs!$B$13)*A6/Inputs!$B$15),IF(Inputs!$B$16="S-Curve",Inputs!$B$13+(Inputs!$B$14-Inputs!$B$13)/(1+EXP(-0.25*(A6-Inputs!$B$15/2))),Inputs!$B$13+(Inputs!$B$14-Inputs!$B$13)/(1+EXP(-0.35*(A6-Inputs!$B$15/2))))) | E6: =MIN(Inputs!$B$14,D6) | F6: ='Unit Mix & Market Comps'!$B$11*E6 | G6: =MAX(0,E6-Inputs!$B$17) | H6: =Inputs!$B$18/12 | I6: ='Unit Mix & Market Comps'!$E$11*(1+H6)^(A6-1) | J6: ='Unit Mix & Market Comps'!$B$11*I6*G6 | K6: =J6*(Inputs!$B$19+Inputs!$B$20)+Inputs!$B$21 | L6: =J6+K6
A7: 4 | B7: =ROUNDUP(A7/12,0) | C7: =E6 | D7: =IF(Inputs!$B$16="Linear",MIN(Inputs!$B$14,Inputs!$B$13+(Inputs!$B$14-Inputs!$B$13)*A7/Inputs!$B$15),IF(Inputs!$B$16="S-Curve",Inputs!$B$13+(Inputs!$B$14-Inputs!$B$13)/(1+EXP(-0.25*(A7-Inputs!$B$15/2))),Inputs!$B$13+(Inputs!$B$14-Inputs!$B$13)/(1+EXP(-0.35*(A7-Inputs!$B$15/2))))) | E7: =MIN(Inputs!$B$14,D7) | F7: ='Unit Mix & Market Comps'!$B$11*E7 | G7: =MAX(0,E7-Inputs!$B$17) | H7: =Inputs!$B$18/12 | I7: ='Unit Mix & Market Comps'!$E$11*(1+H7)^(A7-1) | J7: ='Unit Mix & Market Comps'!$B$11*I7*G7 | K7: =J7*(Inputs!$B$19+Inputs!$B$20)+Inputs!$B$21 | L7: =J7+K7
A8: 5 | B8: =ROUNDUP(A8/12,0) | C8: =E7 | D8: =IF(Inputs!$B$16="Linear",MIN(Inputs!$B$14,Inputs!$B$13+(Inputs!$B$14-Inputs!$B$13)*A8/Inputs!$B$15),IF(Inputs!$B$16="S-Curve",Inputs!$B$13+(Inputs!$B$14-Inputs!$B$13)/(1+EXP(-0.25*(A8-Inputs!$B$15/2))),Inputs!$B$13+(Inputs!$B$14-Inputs!$B$13)/(1+EXP(-0.35*(A8-Inputs!$B$15/2))))) | E8: =MIN(Inputs!$B$14,D8) | F8: ='Unit Mix & Market Comps'!$B$11*E8 | G8: =MAX(0,E8-Inputs!$B$17) | H8: =Inputs!$B$18/12 | I8: ='Unit Mix & Market Comps'!$E$11*(1+H8)^(A8-1) | J8: ='Unit Mix & Market Comps'!$B$11*I8*G8 | K8: =J8*(Inputs!$B$19+Inputs!$B$20)+Inputs!$B$21 | L8: =J8+K8
A9: 6 | B9: =ROUNDUP(A9/12,0) | C9: =E8 | D9: =IF(Inputs!$B$16="Linear",MIN(Inputs!$B$14,Inputs!$B$13+(Inputs!$B$14-Inputs!$B$13)*A9/Inputs!$B$15),IF(Inputs!$B$16="S-Curve",Inputs!$B$13+(Inputs!$B$14-Inputs!$B$13)/(1+EXP(-0.25*(A9-Inputs!$B$15/2))),Inputs!$B$13+(Inputs!$B$14-Inputs!$B$13)/(1+EXP(-0.35*(A9-Inputs!$B$15/2))))) | E9: =MIN(Inputs!$B$14,D9) | F9: ='Unit Mix & Market Comps'!$B$11*E9 | G9: =MAX(0,E9-Inputs!$B$17) | H9: =Inputs!$B$18/12 | I9: ='Unit Mix & Market Comps'!$E$11*(1+H9)^(A9-1) | J9: ='Unit Mix & Market Comps'!$B$11*I9*G9 | K9: =J9*(Inputs!$B$19+Inputs!$B$20)+Inputs!$B$21 | L9: =J9+K9
A10: 7 | B10: =ROUNDUP(A10/12,0) | C10: =E9 | D10: =IF(Inputs!$B$16="Linear",MIN(Inputs!$B$14,Inputs!$B$13+(Inputs!$B$14-Inputs!$B$13)*A10/Inputs!$B$15),IF(Inputs!$B$16="S-Curve",Inputs!$B$13+(Inputs!$B$14-Inputs!$B$13)/(1+EXP(-0.25*(A10-Inputs!$B$15/2))),Inputs!$B$13+(Inputs!$B$14-Inputs!$B$13)/(1+EXP(-0.35*(A10-Inputs!$B$15/2))))) | E10: =MIN(Inputs!$B$14,D10) | F10: ='Unit Mix & Market Comps'!$B$11*E10 | G10: =MAX(0,E10-Inputs!$B$17) | H10: =Inputs!$B$18/12 | I10: ='Unit Mix & Market Comps'!$E$11*(1+H10)^(A10-1) | J10: ='Unit Mix & Market Comps'!$B$11*I10*G10 | K10: =J10*(Inputs!$B$19+Inputs!$B$20)+Inputs!$B$21 | L10: =J10+K10
A11: 8 | B11: =ROUNDUP(A11/12,0) | C11: =E10 | D11: =IF(Inputs!$B$16="Linear",MIN(Inputs!$B$14,Inputs!$B$13+(Inputs!$B$14-Inputs!$B$13)*A11/Inputs!$B$15),IF(Inputs!$B$16="S-Curve",Inputs!$B$13+(Inputs!$B$14-Inputs!$B$13)/(1+EXP(-0.25*(A11-Inputs!$B$15/2))),Inputs!$B$13+(Inputs!$B$14-Inputs!$B$13)/(1+EXP(-0.35*(A11-Inputs!$B$15/2))))) | E11: =MIN(Inputs!$B$14,D11) | F11: ='Unit Mix & Market Comps'!$B$11*E11 | G11: =MAX(0,E11-Inputs!$B$17) | H11: =Inputs!$B$18/12 | I11: ='Unit Mix & Market Comps'!$E$11*(1+H11)^(A11-1) | J11: ='Unit Mix & Market Comps'!$B$11*I11*G11 | K11: =J11*(Inputs!$B$19+Inputs!$B$20)+Inputs!$B$21 | L11: =J11+K11
A12: 9 | B12: =ROUNDUP(A12/12,0) | C12: =E11 | D12: =IF(Inputs!$B$16="Linear",MIN(Inputs!$B$14,Inputs!$B$13+(Inputs!$B$14-Inputs!$B$13)*A12/Inputs!$B$15),IF(Inputs!$B$16="S-Curve",Inputs!$B$13+(Inputs!$B$14-Inputs!$B$13)/(1+EXP(-0.25*(A12-Inputs!$B$15/2))),Inputs!$B$13+(Inputs!$B$14-Inputs!$B$13)/(1+EXP(-0.35*(A12-Inputs!$B$15/2))))) | E12: =MIN(Inputs!$B$14,D12) | F12: ='Unit Mix & Market Comps'!$B$11*E12 | G12: =MAX(0,E12-Inputs!$B$17) | H12: =Inputs!$B$18/12 | I12: ='Unit Mix & Market Comps'!$E$11*(1+H12)^(A12-1) | J12: ='Unit Mix & Market Comps'!$B$11*I12*G12 | K12: =J12*(Inputs!$B$19+Inputs!$B$20)+Inputs!$B$21 | L12: =J12+K12
A13: 10 | B13: =ROUNDUP(A13/12,0) | C13: =E12 | D13: =IF(Inputs!$B$16="Linear",MIN(Inputs!$B$14,Inputs!$B$13+(Inputs!$B$14-Inputs!$B$13)*A13/Inputs!$B$15),IF(Inputs!$B$16="S-Curve",Inputs!$B$13+(Inputs!$B$14-Inputs!$B$13)/(1+EXP(-0.25*(A13-Inputs!$B$15/2))),Inputs!$B$13+(Inputs!$B$14-Inputs!$B$13)/(1+EXP(-0.35*(A13-Inputs!$B$15/2))))) | E13: =MIN(Inputs!$B$14,D13) | F13: ='Unit Mix & Market Comps'!$B$11*E13 | G13: =MAX(0,E13-Inputs!$B$17) | H13: =Inputs!$B$18/12 | I13: ='Unit Mix & Market Comps'!$E$11*(1+H13)^(A13-1) | J13: ='Unit Mix & Market Comps'!$B$11*I13*G13 | K13: =J13*(Inputs!$B$19+Inputs!$B$20)+Inputs!$B$21 | L13: =J13+K13
A14: 11 | B14: =ROUNDUP(A14/12,0) | C14: =E13 | D14: =IF(Inputs!$B$16="Linear",MIN(Inputs!$B$14,Inputs!$B$13+(Inputs!$B$14-Inputs!$B$13)*A14/Inputs!$B$15),IF(Inputs!$B$16="S-Curve",Inputs!$B$13+(Inputs!$B$14-Inputs!$B$13)/(1+EXP(-0.25*(A14-Inputs!$B$15/2))),Inputs!$B$13+(Inputs!$B$14-Inputs!$B$13)/(1+EXP(-0.35*(A14-Inputs!$B$15/2))))) | E14: =MIN(Inputs!$B$14,D14) | F14: ='Unit Mix & Market Comps'!$B$11*E14 | G14: =MAX(0,E14-Inputs!$B$17) | H14: =Inputs!$B$18/12 | I14: ='Unit Mix & Market Comps'!$E$11*(1+H14)^(A14-1) | J14: ='Unit Mix & Market Comps'!$B$11*I14*G14 | K14: =J14*(Inputs!$B$19+Inputs!$B$20)+Inputs!$B$21 | L14: =J14+K14
A15: 12 | B15: =ROUNDUP(A15/12,0) | C15: =E14 | D15: =IF(Inputs!$B$16="Linear",MIN(Inputs!$B$14,Inputs!$B$13+(Inputs!$B$14-Inputs!$B$13)*A15/Inputs!$B$15),IF(Inputs!$B$16="S-Curve",Inputs!$B$13+(Inputs!$B$14-Inputs!$B$13)/(1+EXP(-0.25*(A15-Inputs!$B$15/2))),Inputs!$B$13+(Inputs!$B$14-Inputs!$B$13)/(1+EXP(-0.35*(A15-Inputs!$B$15/2))))) | E15: =MIN(Inputs!$B$14,D15) | F15: ='Unit Mix & Market Comps'!$B$11*E15 | G15: =MAX(0,E15-Inputs!$B$17) | H15: =Inputs!$B$18/12 | I15: ='Unit Mix & Market Comps'!$E$11*(1+H15)^(A15-1) | J15: ='Unit Mix & Market Comps'!$B$11*I15*G15 | K15: =J15*(Inputs!$B$19+Inputs!$B$20)+Inputs!$B$21 | L15: =J15+K15
A16: 13 | B16: =ROUNDUP(A16/12,0) | C16: =E15 | D16: =IF(Inputs!$B$16="Linear",MIN(Inputs!$B$14,Inputs!$B$13+(Inputs!$B$14-Inputs!$B$13)*A16/Inputs!$B$15),IF(Inputs!$B$16="S-Curve",Inputs!$B$13+(Inputs!$B$14-Inputs!$B$13)/(1+EXP(-0.25*(A16-Inputs!$B$15/2))),Inputs!$B$13+(Inputs!$B$14-Inputs!$B$13)/(1+EXP(-0.35*(A16-Inputs!$B$15/2))))) | E16: =MIN(Inputs!$B$14,D16) | F16: ='Unit Mix & Market Comps'!$B$11*E16 | G16: =MAX(0,E16-Inputs!$B$17) | H16: =Inputs!$B$18/12 | I16: ='Unit Mix & Market Comps'!$E$11*(1+H16)^(A16-1) | J16: ='Unit Mix & Market Comps'!$B$11*I16*G16 | K16: =J16*(Inputs!$B$19+Inputs!$B$20)+Inputs!$B$21 | L16: =J16+K16
... A63: 60 | B63: =ROUNDUP(A63/12,0) | C63: =E62 | D63: =IF(Inputs!$B$16="Linear",MIN(Inputs!$B$14,Inputs!$B$13+(Inputs!$B$14-Inputs!$B$13)*A63/Inputs!$B$15),IF(Inputs!$B$16="S-Curve",Inputs!$B$13+(Inputs!$B$14-Inputs!$B$13)/(1+EXP(-0.25*(A63-Inputs!$B$15/2))),Inputs!$B$13+(Inputs!$B$14-Inputs!$B$13)/(1+EXP(-0.35*(A63-Inputs!$B$15/2))))) | E63: =MIN(Inputs!$B$14,D63) | F63: ='Unit Mix & Market Comps'!$B$11*E63 | G63: =MAX(0,E63-Inputs!$B$17) | H63: =Inputs!$B$18/12 | I63: ='Unit Mix & Market Comps'!$E$11*(1+H63)^(A63-1) | J63: ='Unit Mix & Market Comps'!$B$11*I63*G63 | K63: =J63*(Inputs!$B$19+Inputs!$B$20)+Inputs!$B$21 | L63: =J63+K63

Sheet Revenue Forecast
A1: Annual Revenue Forecast
A3: Year | B3: Avg Economic Occ. | C3: Rental Revenue | D3: Ancillary Income | E3: Expansion Revenue | F3: Total EGI | G3: EGI Growth
A4: 1 | B4: =AVERAGE('Monthly Lease-Up'!G4:G15) | C4: =SUM('Monthly Lease-Up'!J4:J15) | D4: =SUM('Monthly Lease-Up'!K4:K15) | E4: =SUM('Expansion CapEx'!E17:E28) | F4: =C4+D4+E4 | G4: -
A5: 2 | B5: =AVERAGE('Monthly Lease-Up'!G16:G27) | C5: =SUM('Monthly Lease-Up'!J16:J27) | D5: =SUM('Monthly Lease-Up'!K16:K27) | E5: =SUM('Expansion CapEx'!E29:E40) | F5: =C5+D5+E5 | G5: =F5/F4-1
A6: 3 | B6: =AVERAGE('Monthly Lease-Up'!G28:G39) | C6: =SUM('Monthly Lease-Up'!J28:J39) | D6: =SUM('Monthly Lease-Up'!K28:K39) | E6: =SUM('Expansion CapEx'!E41:E52) | F6: =C6+D6+E6 | G6: =F6/F5-1
A7: 4 | B7: =AVERAGE('Monthly Lease-Up'!G40:G51) | C7: =SUM('Monthly Lease-Up'!J40:J51) | D7: =SUM('Monthly Lease-Up'!K40:K51) | E7: =SUM('Expansion CapEx'!E53:E64) | F7: =C7+D7+E7 | G7: =F7/F6-1
A8: 5 | B8: =AVERAGE('Monthly Lease-Up'!G52:G63) | C8: =SUM('Monthly Lease-Up'!J52:J63) | D8: =SUM('Monthly Lease-Up'!K52:K63) | E8: =SUM('Expansion CapEx'!E65:E76) | F8: =C8+D8+E8 | G8: =F8/F7-1

Sheet Operating Expenses
A1: Operating Expense Forecast
A4: Expense Line | B4: Year 1 | C4: Year 2 | D4: Year 3 | E4: Year 4 | F4: Year 5 | G4: % EGI Y1
A5: Property Taxes | B5: 130000 | C5: =B5*(1+Inputs!$B$22)^1 | D5: =B5*(1+Inputs!$B$22)^2 | E5: =B5*(1+Inputs!$B$22)^3 | F5: =B5*(1+Inputs!$B$22)^4 | G5: =B5/'Revenue Forecast'!$F$4
A6: Insurance | B6: 45000 | C6: =B6*(1+Inputs!$B$22)^1 | D6: =B6*(1+Inputs!$B$22)^2 | E6: =B6*(1+Inputs!$B$22)^3 | F6: =B6*(1+Inputs!$B$22)^4 | G6: =B6/'Revenue Forecast'!$F$4
A7: Utilities | B7: 60000 | C7: =B7*(1+Inputs!$B$22)^1 | D7: =B7*(1+Inputs!$B$22)^2 | E7: =B7*(1+Inputs!$B$22)^3 | F7: =B7*(1+Inputs!$B$22)^4 | G7: =B7/'Revenue Forecast'!$F$4
A8: Repairs & Maintenance | B8: 65000 | C8: =B8*(1+Inputs!$B$22)^1 | D8: =B8*(1+Inputs!$B$22)^2 | E8: =B8*(1+Inputs!$B$22)^3 | F8: =B8*(1+Inputs!$B$22)^4 | G8: =B8/'Revenue Forecast'!$F$4
A9: Payroll / On-Site Staff | B9: 90000 | C9: =B9*(1+Inputs!$B$22)^1 | D9: =B9*(1+Inputs!$B$22)^2 | E9: =B9*(1+Inputs!$B$22)^3 | F9: =B9*(1+Inputs!$B$22)^4 | G9: =B9/'Revenue Forecast'!$F$4
A10: Management Fee | B10: ='Revenue Forecast'!F4*3.5% | C10: =B10*(1+Inputs!$B$22)^1 | D10: =B10*(1+Inputs!$B$22)^2 | E10: =B10*(1+Inputs!$B$22)^3 | F10: =B10*(1+Inputs!$B$22)^4 | G10: =B10/'Revenue Forecast'!$F$4
A11: Marketing / Admin | B11: 40000 | C11: =B11*(1+Inputs!$B$22)^1 | D11: =B11*(1+Inputs!$B$22)^2 | E11: =B11*(1+Inputs!$B$22)^3 | F11: =B11*(1+Inputs!$B$22)^4 | G11: =B11/'Revenue Forecast'!$F$4
A12: Software / Call Center | B12: 30000 | C12: =B12*(1+Inputs!$B$22)^1 | D12: =B12*(1+Inputs!$B$22)^2 | E12: =B12*(1+Inputs!$B$22)^3 | F12: =B12*(1+Inputs!$B$22)^4 | G12: =B12/'Revenue Forecast'!$F$4
A13: Bad Debt / Concessions | B13: ='Revenue Forecast'!F4*1.5% | C13: =B13*(1+Inputs!$B$22)^1 | D13: =B13*(1+Inputs!$B$22)^2 | E13: =B13*(1+Inputs!$B$22)^3 | F13: =B13*(1+Inputs!$B$22)^4 | G13: =B13/'Revenue Forecast'!$F$4
A14: Replacement Reserves | B14: 25000 | C14: =B14*(1+Inputs!$B$22)^1 | D14: =B14*(1+Inputs!$B$22)^2 | E14: =B14*(1+Inputs!$B$22)^3 | F14: =B14*(1+Inputs!$B$22)^4 | G14: =B14/'Revenue Forecast'!$F$4
A15: Total Operating Expenses | B15: =SUM(B5:B14) | C15: =SUM(C5:C14) | D15: =SUM(D5:D14) | E15: =SUM(E5:E14) | F15: =SUM(F5:F14) | G15: =B15/'Revenue Forecast'!$F$4
A17: NOI | B17: ='Revenue Forecast'!F4-B15 | C17: ='Revenue Forecast'!F5-C15 | D17: ='Revenue Forecast'!F6-D15 | E17: ='Revenue Forecast'!F7-E15 | F17: ='Revenue Forecast'!F8-F15 | G17: =B17/'Revenue Forecast'!$F$4

Sheet Expansion CapEx
A1: Expansion / Construction Module
A3: Expansion Assumptions
A4: Expansion Enabled? | B4: 1
A5: Expansion Start Month | B5: 13
A6: Construction Duration Months | B6: 12
A7: New Rentable Units | B7: 150
A8: Avg New Unit Monthly Rent | B8: 175
A9: Stabilized Occ. on New Units | B9: 0.88
A10: Cost Per New Unit | B10: 8500
A11: Soft Costs % | B11: 0.12
A12: Contingency % | B12: 0.1
A16: Month | B16: Construction Spend | C16: Cumulative Spend | D16: New Unit Occ. | E16: New Unit Revenue | F16: Incremental NOI @ 65% Margin
A17: 1 | B17: =IF(AND($B$4=1,A17>=$B$5,A17<$B$5+$B$6),($B$7*$B$10*(1+$B$11+$B$12))/$B$6,0) | C17: =SUM($B$17:B17) | D17: =IF(A17<$B$5+$B$6,0,MIN($B$9,(A17-($B$5+$B$6))/12*$B$9)) | E17: =$B$7*$B$8*D17 | F17: =E17*65%
A18: 2 | B18: =IF(AND($B$4=1,A18>=$B$5,A18<$B$5+$B$6),($B$7*$B$10*(1+$B$11+$B$12))/$B$6,0) | C18: =SUM($B$17:B18) | D18: =IF(A18<$B$5+$B$6,0,MIN($B$9,(A18-($B$5+$B$6))/12*$B$9)) | E18: =$B$7*$B$8*D18 | F18: =E18*65%
A19: 3 | B19: =IF(AND($B$4=1,A19>=$B$5,A19<$B$5+$B$6),($B$7*$B$10*(1+$B$11+$B$12))/$B$6,0) | C19: =SUM($B$17:B19) | D19: =IF(A19<$B$5+$B$6,0,MIN($B$9,(A19-($B$5+$B$6))/12*$B$9)) | E19: =$B$7*$B$8*D19 | F19: =E19*65%
A20: 4 | B20: =IF(AND($B$4=1,A20>=$B$5,A20<$B$5+$B$6),($B$7*$B$10*(1+$B$11+$B$12))/$B$6,0) | C20: =SUM($B$17:B20) | D20: =IF(A20<$B$5+$B$6,0,MIN($B$9,(A20-($B$5+$B$6))/12*$B$9)) | E20: =$B$7*$B$8*D20 | F20: =E20*65%
A21: 5 | B21: =IF(AND($B$4=1,A21>=$B$5,A21<$B$5+$B$6),($B$7*$B$10*(1+$B$11+$B$12))/$B$6,0) | C21: =SUM($B$17:B21) | D21: =IF(A21<$B$5+$B$6,0,MIN($B$9,(A21-($B$5+$B$6))/12*$B$9)) | E21: =$B$7*$B$8*D21 | F21: =E21*65%
A22: 6 | B22: =IF(AND($B$4=1,A22>=$B$5,A22<$B$5+$B$6),($B$7*$B$10*(1+$B$11+$B$12))/$B$6,0) | C22: =SUM($B$17:B22) | D22: =IF(A22<$B$5+$B$6,0,MIN($B$9,(A22-($B$5+$B$6))/12*$B$9)) | E22: =$B$7*$B$8*D22 | F22: =E22*65%
A23: 7 | B23: =IF(AND($B$4=1,A23>=$B$5,A23<$B$5+$B$6),($B$7*$B$10*(1+$B$11+$B$12))/$B$6,0) | C23: =SUM($B$17:B23) | D23: =IF(A23<$B$5+$B$6,0,MIN($B$9,(A23-($B$5+$B$6))/12*$B$9)) | E23: =$B$7*$B$8*D23 | F23: =E23*65%
A24: 8 | B24: =IF(AND($B$4=1,A24>=$B$5,A24<$B$5+$B$6),($B$7*$B$10*(1+$B$11+$B$12))/$B$6,0) | C24: =SUM($B$17:B24) | D24: =IF(A24<$B$5+$B$6,0,MIN($B$9,(A24-($B$5+$B$6))/12*$B$9)) | E24: =$B$7*$B$8*D24 | F24: =E24*65%
A25: 9 | B25: =IF(AND($B$4=1,A25>=$B$5,A25<$B$5+$B$6),($B$7*$B$10*(1+$B$11+$B$12))/$B$6,0) | C25: =SUM($B$17:B25) | D25: =IF(A25<$B$5+$B$6,0,MIN($B$9,(A25-($B$5+$B$6))/12*$B$9)) | E25: =$B$7*$B$8*D25 | F25: =E25*65%
A26: 10 | B26: =IF(AND($B$4=1,A26>=$B$5,A26<$B$5+$B$6),($B$7*$B$10*(1+$B$11+$B$12))/$B$6,0) | C26: =SUM($B$17:B26) | D26: =IF(A26<$B$5+$B$6,0,MIN($B$9,(A26-($B$5+$B$6))/12*$B$9)) | E26: =$B$7*$B$8*D26 | F26: =E26*65%
A27: 11 | B27: =IF(AND($B$4=1,A27>=$B$5,A27<$B$5+$B$6),($B$7*$B$10*(1+$B$11+$B$12))/$B$6,0) | C27: =SUM($B$17:B27) | D27: =IF(A27<$B$5+$B$6,0,MIN($B$9,(A27-($B$5+$B$6))/12*$B$9)) | E27: =$B$7*$B$8*D27 | F27: =E27*65%
A28: 12 | B28: =IF(AND($B$4=1,A28>=$B$5,A28<$B$5+$B$6),($B$7*$B$10*(1+$B$11+$B$12))/$B$6,0) | C28: =SUM($B$17:B28) | D28: =IF(A28<$B$5+$B$6,0,MIN($B$9,(A28-($B$5+$B$6))/12*$B$9)) | E28: =$B$7*$B$8*D28 | F28: =E28*65%
... A76: 60 | B76: =IF(AND($B$4=1,A76>=$B$5,A76<$B$5+$B$6),($B$7*$B$10*(1+$B$11+$B$12))/$B$6,0) | C76: =SUM($B$17:B76) | D76: =IF(A76<$B$5+$B$6,0,MIN($B$9,(A76-($B$5+$B$6))/12*$B$9)) | E76: =$B$7*$B$8*D76 | F76: =E76*65%

Sheet Debt & Refi
A1: Debt Schedule / Refinance Scenario
A3: Initial Debt Sizing
A4: Total Project Cost | B4: =Inputs!B4*(1+Inputs!B5)+Inputs!B6+Inputs!B7*Inputs!B4
A5: Initial Loan Amount | B5: =IF(Inputs!$B$49="Yes",0,Inputs!B4*Inputs!B25)
A6: Initial Equity Required | B6: =B4-B5
A7: Annual Debt Service | B7: =IF(Inputs!$B$49="Yes",0,PMT(Inputs!B27/12,Inputs!B28*12,-B5)*12)
A8: Debt Yield - Year 1 | B8: =IF(OR(Inputs!$B$49="Yes",$B$5=0),"N/A",'Operating Expenses'!B17/$B$5)
A9: DSCR - Year 1 | B9: =IF(OR(Inputs!$B$49="Yes",$B$7=0),"N/A",'Operating Expenses'!B17/$B$7)
A11: Debt Toggle | B11: =Inputs!B50
A13: Month | B13: Beginning Loan | C13: Scheduled Debt Service | D13: Interest | E13: Principal | F13: Ending Loan | G13: Refi Value | H13: Refi Loan | I13: Refi Proceeds | J13: Active Loan Balance
A14: 1 | B14: =IF(Inputs!$B$49="Yes",0,$B$5) | C14: =IF(Inputs!$B$49="Yes",0,IF(A14<Inputs!$B$28,Inputs!$B$26/12*B14,PMT(Inputs!$B$26/12,Inputs!$B$27*12,-B14))) | D14: =IF(Inputs!$B$49="Yes",0,B14*Inputs!$B$26/12) | E14: =IF(Inputs!$B$49="Yes",0,MAX(0,C14-D14)) | F14: =IF(Inputs!$B$49="Yes",0,MAX(0,B14-E14)) | G14: =IF(Inputs!$B$49="Yes",0,IF(A14=Inputs!$B$30,('Operating Expenses'!D17*4)/Inputs!$B$35,0)) | H14: =IF(Inputs!$B$49="Yes",0,IF(A14=Inputs!$B$30,G14*Inputs!$B$31,0)) | I14: =IF(Inputs!$B$49="Yes",0,IF(A14=Inputs!$B$30,MAX(0,H14-F14),0)) | J14: =IF(Inputs!$B$49="Yes",0,IF(A14=Inputs!$B$30,H14,F14))
A15: 2 | B15: =IF(Inputs!$B$49="Yes",0,J14) | C15: =IF(Inputs!$B$49="Yes",0,IF(A15<Inputs!$B$28,Inputs!$B$26/12*B15,PMT(Inputs!$B$26/12,Inputs!$B$27*12,-B15))) | D15: =IF(Inputs!$B$49="Yes",0,B15*Inputs!$B$26/12) | E15: =IF(Inputs!$B$49="Yes",0,MAX(0,C15-D15)) | F15: =IF(Inputs!$B$49="Yes",0,MAX(0,B15-E15)) | G15: =IF(Inputs!$B$49="Yes",0,IF(A15=Inputs!$B$30,('Operating Expenses'!D17*4)/Inputs!$B$35,0)) | H15: =IF(Inputs!$B$49="Yes",0,IF(A15=Inputs!$B$30,G15*Inputs!$B$31,0)) | I15: =IF(Inputs!$B$49="Yes",0,IF(A15=Inputs!$B$30,MAX(0,H15-F15),0)) | J15: =IF(Inputs!$B$49="Yes",0,IF(A15=Inputs!$B$30,H15,F15))
A16: 3 | B16: =IF(Inputs!$B$49="Yes",0,J15) | C16: =IF(Inputs!$B$49="Yes",0,IF(A16<Inputs!$B$28,Inputs!$B$26/12*B16,PMT(Inputs!$B$26/12,Inputs!$B$27*12,-B16))) | D16: =IF(Inputs!$B$49="Yes",0,B16*Inputs!$B$26/12) | E16: =IF(Inputs!$B$49="Yes",0,MAX(0,C16-D16)) | F16: =IF(Inputs!$B$49="Yes",0,MAX(0,B16-E16)) | G16: =IF(Inputs!$B$49="Yes",0,IF(A16=Inputs!$B$30,('Operating Expenses'!D17*4)/Inputs!$B$35,0)) | H16: =IF(Inputs!$B$49="Yes",0,IF(A16=Inputs!$B$30,G16*Inputs!$B$31,0)) | I16: =IF(Inputs!$B$49="Yes",0,IF(A16=Inputs!$B$30,MAX(0,H16-F16),0)) | J16: =IF(Inputs!$B$49="Yes",0,IF(A16=Inputs!$B$30,H16,F16))
A17: 4 | B17: =IF(Inputs!$B$49="Yes",0,J16) | C17: =IF(Inputs!$B$49="Yes",0,IF(A17<Inputs!$B$28,Inputs!$B$26/12*B17,PMT(Inputs!$B$26/12,Inputs!$B$27*12,-B17))) | D17: =IF(Inputs!$B$49="Yes",0,B17*Inputs!$B$26/12) | E17: =IF(Inputs!$B$49="Yes",0,MAX(0,C17-D17)) | F17: =IF(Inputs!$B$49="Yes",0,MAX(0,B17-E17)) | G17: =IF(Inputs!$B$49="Yes",0,IF(A17=Inputs!$B$30,('Operating Expenses'!D17*4)/Inputs!$B$35,0)) | H17: =IF(Inputs!$B$49="Yes",0,IF(A17=Inputs!$B$30,G17*Inputs!$B$31,0)) | I17: =IF(Inputs!$B$49="Yes",0,IF(A17=Inputs!$B$30,MAX(0,H17-F17),0)) | J17: =IF(Inputs!$B$49="Yes",0,IF(A17=Inputs!$B$30,H17,F17))
A18: 5 | B18: =IF(Inputs!$B$49="Yes",0,J17) | C18: =IF(Inputs!$B$49="Yes",0,IF(A18<Inputs!$B$28,Inputs!$B$26/12*B18,PMT(Inputs!$B$26/12,Inputs!$B$27*12,-B18))) | D18: =IF(Inputs!$B$49="Yes",0,B18*Inputs!$B$26/12) | E18: =IF(Inputs!$B$49="Yes",0,MAX(0,C18-D18)) | F18: =IF(Inputs!$B$49="Yes",0,MAX(0,B18-E18)) | G18: =IF(Inputs!$B$49="Yes",0,IF(A18=Inputs!$B$30,('Operating Expenses'!D17*4)/Inputs!$B$35,0)) | H18: =IF(Inputs!$B$49="Yes",0,IF(A18=Inputs!$B$30,G18*Inputs!$B$31,0)) | I18: =IF(Inputs!$B$49="Yes",0,IF(A18=Inputs!$B$30,MAX(0,H18-F18),0)) | J18: =IF(Inputs!$B$49="Yes",0,IF(A18=Inputs!$B$30,H18,F18))
A19: 6 | B19: =IF(Inputs!$B$49="Yes",0,J18) | C19: =IF(Inputs!$B$49="Yes",0,IF(A19<Inputs!$B$28,Inputs!$B$26/12*B19,PMT(Inputs!$B$26/12,Inputs!$B$27*12,-B19))) | D19: =IF(Inputs!$B$49="Yes",0,B19*Inputs!$B$26/12) | E19: =IF(Inputs!$B$49="Yes",0,MAX(0,C19-D19)) | F19: =IF(Inputs!$B$49="Yes",0,MAX(0,B19-E19)) | G19: =IF(Inputs!$B$49="Yes",0,IF(A19=Inputs!$B$30,('Operating Expenses'!D17*4)/Inputs!$B$35,0)) | H19: =IF(Inputs!$B$49="Yes",0,IF(A19=Inputs!$B$30,G19*Inputs!$B$31,0)) | I19: =IF(Inputs!$B$49="Yes",0,IF(A19=Inputs!$B$30,MAX(0,H19-F19),0)) | J19: =IF(Inputs!$B$49="Yes",0,IF(A19=Inputs!$B$30,H19,F19))
A20: 7 | B20: =IF(Inputs!$B$49="Yes",0,J19) | C20: =IF(Inputs!$B$49="Yes",0,IF(A20<Inputs!$B$28,Inputs!$B$26/12*B20,PMT(Inputs!$B$26/12,Inputs!$B$27*12,-B20))) | D20: =IF(Inputs!$B$49="Yes",0,B20*Inputs!$B$26/12) | E20: =IF(Inputs!$B$49="Yes",0,MAX(0,C20-D20)) | F20: =IF(Inputs!$B$49="Yes",0,MAX(0,B20-E20)) | G20: =IF(Inputs!$B$49="Yes",0,IF(A20=Inputs!$B$30,('Operating Expenses'!D17*4)/Inputs!$B$35,0)) | H20: =IF(Inputs!$B$49="Yes",0,IF(A20=Inputs!$B$30,G20*Inputs!$B$31,0)) | I20: =IF(Inputs!$B$49="Yes",0,IF(A20=Inputs!$B$30,MAX(0,H20-F20),0)) | J20: =IF(Inputs!$B$49="Yes",0,IF(A20=Inputs!$B$30,H20,F20))
A21: 8 | B21: =IF(Inputs!$B$49="Yes",0,J20) | C21: =IF(Inputs!$B$49="Yes",0,IF(A21<Inputs!$B$28,Inputs!$B$26/12*B21,PMT(Inputs!$B$26/12,Inputs!$B$27*12,-B21))) | D21: =IF(Inputs!$B$49="Yes",0,B21*Inputs!$B$26/12) | E21: =IF(Inputs!$B$49="Yes",0,MAX(0,C21-D21)) | F21: =IF(Inputs!$B$49="Yes",0,MAX(0,B21-E21)) | G21: =IF(Inputs!$B$49="Yes",0,IF(A21=Inputs!$B$30,('Operating Expenses'!D17*4)/Inputs!$B$35,0)) | H21: =IF(Inputs!$B$49="Yes",0,IF(A21=Inputs!$B$30,G21*Inputs!$B$31,0)) | I21: =IF(Inputs!$B$49="Yes",0,IF(A21=Inputs!$B$30,MAX(0,H21-F21),0)) | J21: =IF(Inputs!$B$49="Yes",0,IF(A21=Inputs!$B$30,H21,F21))
A22: 9 | B22: =IF(Inputs!$B$49="Yes",0,J21) | C22: =IF(Inputs!$B$49="Yes",0,IF(A22<Inputs!$B$28,Inputs!$B$26/12*B22,PMT(Inputs!$B$26/12,Inputs!$B$27*12,-B22))) | D22: =IF(Inputs!$B$49="Yes",0,B22*Inputs!$B$26/12) | E22: =IF(Inputs!$B$49="Yes",0,MAX(0,C22-D22)) | F22: =IF(Inputs!$B$49="Yes",0,MAX(0,B22-E22)) | G22: =IF(Inputs!$B$49="Yes",0,IF(A22=Inputs!$B$30,('Operating Expenses'!D17*4)/Inputs!$B$35,0)) | H22: =IF(Inputs!$B$49="Yes",0,IF(A22=Inputs!$B$30,G22*Inputs!$B$31,0)) | I22: =IF(Inputs!$B$49="Yes",0,IF(A22=Inputs!$B$30,MAX(0,H22-F22),0)) | J22: =IF(Inputs!$B$49="Yes",0,IF(A22=Inputs!$B$30,H22,F22))
A23: 10 | B23: =IF(Inputs!$B$49="Yes",0,J22) | C23: =IF(Inputs!$B$49="Yes",0,IF(A23<Inputs!$B$28,Inputs!$B$26/12*B23,PMT(Inputs!$B$26/12,Inputs!$B$27*12,-B23))) | D23: =IF(Inputs!$B$49="Yes",0,B23*Inputs!$B$26/12) | E23: =IF(Inputs!$B$49="Yes",0,MAX(0,C23-D23)) | F23: =IF(Inputs!$B$49="Yes",0,MAX(0,B23-E23)) | G23: =IF(Inputs!$B$49="Yes",0,IF(A23=Inputs!$B$30,('Operating Expenses'!D17*4)/Inputs!$B$35,0)) | H23: =IF(Inputs!$B$49="Yes",0,IF(A23=Inputs!$B$30,G23*Inputs!$B$31,0)) | I23: =IF(Inputs!$B$49="Yes",0,IF(A23=Inputs!$B$30,MAX(0,H23-F23),0)) | J23: =IF(Inputs!$B$49="Yes",0,IF(A23=Inputs!$B$30,H23,F23))
A24: 11 | B24: =IF(Inputs!$B$49="Yes",0,J23) | C24: =IF(Inputs!$B$49="Yes",0,IF(A24<Inputs!$B$28,Inputs!$B$26/12*B24,PMT(Inputs!$B$26/12,Inputs!$B$27*12,-B24))) | D24: =IF(Inputs!$B$49="Yes",0,B24*Inputs!$B$26/12) | E24: =IF(Inputs!$B$49="Yes",0,MAX(0,C24-D24)) | F24: =IF(Inputs!$B$49="Yes",0,MAX(0,B24-E24)) | G24: =IF(Inputs!$B$49="Yes",0,IF(A24=Inputs!$B$30,('Operating Expenses'!D17*4)/Inputs!$B$35,0)) | H24: =IF(Inputs!$B$49="Yes",0,IF(A24=Inputs!$B$30,G24*Inputs!$B$31,0)) | I24: =IF(Inputs!$B$49="Yes",0,IF(A24=Inputs!$B$30,MAX(0,H24-F24),0)) | J24: =IF(Inputs!$B$49="Yes",0,IF(A24=Inputs!$B$30,H24,F24))
A25: 12 | B25: =IF(Inputs!$B$49="Yes",0,J24) | C25: =IF(Inputs!$B$49="Yes",0,IF(A25<Inputs!$B$28,Inputs!$B$26/12*B25,PMT(Inputs!$B$26/12,Inputs!$B$27*12,-B25))) | D25: =IF(Inputs!$B$49="Yes",0,B25*Inputs!$B$26/12) | E25: =IF(Inputs!$B$49="Yes",0,MAX(0,C25-D25)) | F25: =IF(Inputs!$B$49="Yes",0,MAX(0,B25-E25)) | G25: =IF(Inputs!$B$49="Yes",0,IF(A25=Inputs!$B$30,('Operating Expenses'!D17*4)/Inputs!$B$35,0)) | H25: =IF(Inputs!$B$49="Yes",0,IF(A25=Inputs!$B$30,G25*Inputs!$B$31,0)) | I25: =IF(Inputs!$B$49="Yes",0,IF(A25=Inputs!$B$30,MAX(0,H25-F25),0)) | J25: =IF(Inputs!$B$49="Yes",0,IF(A25=Inputs!$B$30,H25,F25))
A26: 13 | B26: =IF(Inputs!$B$49="Yes",0,J25) | C26: =IF(Inputs!$B$49="Yes",0,IF(A26<Inputs!$B$28,Inputs!$B$26/12*B26,PMT(Inputs!$B$26/12,Inputs!$B$27*12,-B26))) | D26: =IF(Inputs!$B$49="Yes",0,B26*Inputs!$B$26/12) | E26: =IF(Inputs!$B$49="Yes",0,MAX(0,C26-D26)) | F26: =IF(Inputs!$B$49="Yes",0,MAX(0,B26-E26)) | G26: =IF(Inputs!$B$49="Yes",0,IF(A26=Inputs!$B$30,('Operating Expenses'!D17*4)/Inputs!$B$35,0)) | H26: =IF(Inputs!$B$49="Yes",0,IF(A26=Inputs!$B$30,G26*Inputs!$B$31,0)) | I26: =IF(Inputs!$B$49="Yes",0,IF(A26=Inputs!$B$30,MAX(0,H26-F26),0)) | J26: =IF(Inputs!$B$49="Yes",0,IF(A26=Inputs!$B$30,H26,F26))
A27: 14 | B27: =IF(Inputs!$B$49="Yes",0,J26) | C27: =IF(Inputs!$B$49="Yes",0,IF(A27<Inputs!$B$28,Inputs!$B$26/12*B27,PMT(Inputs!$B$26/12,Inputs!$B$27*12,-B27))) | D27: =IF(Inputs!$B$49="Yes",0,B27*Inputs!$B$26/12) | E27: =IF(Inputs!$B$49="Yes",0,MAX(0,C27-D27)) | F27: =IF(Inputs!$B$49="Yes",0,MAX(0,B27-E27)) | G27: =IF(Inputs!$B$49="Yes",0,IF(A27=Inputs!$B$30,('Operating Expenses'!D17*4)/Inputs!$B$35,0)) | H27: =IF(Inputs!$B$49="Yes",0,IF(A27=Inputs!$B$30,G27*Inputs!$B$31,0)) | I27: =IF(Inputs!$B$49="Yes",0,IF(A27=Inputs!$B$30,MAX(0,H27-F27),0)) | J27: =IF(Inputs!$B$49="Yes",0,IF(A27=Inputs!$B$30,H27,F27))
A28: 15 | B28: =IF(Inputs!$B$49="Yes",0,J27) | C28: =IF(Inputs!$B$49="Yes",0,IF(A28<Inputs!$B$28,Inputs!$B$26/12*B28,PMT(Inputs!$B$26/12,Inputs!$B$27*12,-B28))) | D28: =IF(Inputs!$B$49="Yes",0,B28*Inputs!$B$26/12) | E28: =IF(Inputs!$B$49="Yes",0,MAX(0,C28-D28)) | F28: =IF(Inputs!$B$49="Yes",0,MAX(0,B28-E28)) | G28: =IF(Inputs!$B$49="Yes",0,IF(A28=Inputs!$B$30,('Operating Expenses'!D17*4)/Inputs!$B$35,0)) | H28: =IF(Inputs!$B$49="Yes",0,IF(A28=Inputs!$B$30,G28*Inputs!$B$31,0)) | I28: =IF(Inputs!$B$49="Yes",0,IF(A28=Inputs!$B$30,MAX(0,H28-F28),0)) | J28: =IF(Inputs!$B$49="Yes",0,IF(A28=Inputs!$B$30,H28,F28))
A29: 16 | B29: =IF(Inputs!$B$49="Yes",0,J28) | C29: =IF(Inputs!$B$49="Yes",0,IF(A29<Inputs!$B$28,Inputs!$B$26/12*B29,PMT(Inputs!$B$26/12,Inputs!$B$27*12,-B29))) | D29: =IF(Inputs!$B$49="Yes",0,B29*Inputs!$B$26/12) | E29: =IF(Inputs!$B$49="Yes",0,MAX(0,C29-D29)) | F29: =IF(Inputs!$B$49="Yes",0,MAX(0,B29-E29)) | G29: =IF(Inputs!$B$49="Yes",0,IF(A29=Inputs!$B$30,('Operating Expenses'!D17*4)/Inputs!$B$35,0)) | H29: =IF(Inputs!$B$49="Yes",0,IF(A29=Inputs!$B$30,G29*Inputs!$B$31,0)) | I29: =IF(Inputs!$B$49="Yes",0,IF(A29=Inputs!$B$30,MAX(0,H29-F29),0)) | J29: =IF(Inputs!$B$49="Yes",0,IF(A29=Inputs!$B$30,H29,F29))
A30: 17 | B30: =IF(Inputs!$B$49="Yes",0,J29) | C30: =IF(Inputs!$B$49="Yes",0,IF(A30<Inputs!$B$28,Inputs!$B$26/12*B30,PMT(Inputs!$B$26/12,Inputs!$B$27*12,-B30))) | D30: =IF(Inputs!$B$49="Yes",0,B30*Inputs!$B$26/12) | E30: =IF(Inputs!$B$49="Yes",0,MAX(0,C30-D30)) | F30: =IF(Inputs!$B$49="Yes",0,MAX(0,B30-E30)) | G30: =IF(Inputs!$B$49="Yes",0,IF(A30=Inputs!$B$30,('Operating Expenses'!D17*4)/Inputs!$B$35,0)) | H30: =IF(Inputs!$B$49="Yes",0,IF(A30=Inputs!$B$30,G30*Inputs!$B$31,0)) | I30: =IF(Inputs!$B$49="Yes",0,IF(A30=Inputs!$B$30,MAX(0,H30-F30),0)) | J30: =IF(Inputs!$B$49="Yes",0,IF(A30=Inputs!$B$30,H30,F30))
A31: 18 | B31: =IF(Inputs!$B$49="Yes",0,J30) | C31: =IF(Inputs!$B$49="Yes",0,IF(A31<Inputs!$B$28,Inputs!$B$26/12*B31,PMT(Inputs!$B$26/12,Inputs!$B$27*12,-B31))) | D31: =IF(Inputs!$B$49="Yes",0,B31*Inputs!$B$26/12) | E31: =IF(Inputs!$B$49="Yes",0,MAX(0,C31-D31)) | F31: =IF(Inputs!$B$49="Yes",0,MAX(0,B31-E31)) | G31: =IF(Inputs!$B$49="Yes",0,IF(A31=Inputs!$B$30,('Operating Expenses'!D17*4)/Inputs!$B$35,0)) | H31: =IF(Inputs!$B$49="Yes",0,IF(A31=Inputs!$B$30,G31*Inputs!$B$31,0)) | I31: =IF(Inputs!$B$49="Yes",0,IF(A31=Inputs!$B$30,MAX(0,H31-F31),0)) | J31: =IF(Inputs!$B$49="Yes",0,IF(A31=Inputs!$B$30,H31,F31))
A32: 19 | B32: =IF(Inputs!$B$49="Yes",0,J31) | C32: =IF(Inputs!$B$49="Yes",0,IF(A32<Inputs!$B$28,Inputs!$B$26/12*B32,PMT(Inputs!$B$26/12,Inputs!$B$27*12,-B32))) | D32: =IF(Inputs!$B$49="Yes",0,B32*Inputs!$B$26/12) | E32: =IF(Inputs!$B$49="Yes",0,MAX(0,C32-D32)) | F32: =IF(Inputs!$B$49="Yes",0,MAX(0,B32-E32)) | G32: =IF(Inputs!$B$49="Yes",0,IF(A32=Inputs!$B$30,('Operating Expenses'!D17*4)/Inputs!$B$35,0)) | H32: =IF(Inputs!$B$49="Yes",0,IF(A32=Inputs!$B$30,G32*Inputs!$B$31,0)) | I32: =IF(Inputs!$B$49="Yes",0,IF(A32=Inputs!$B$30,MAX(0,H32-F32),0)) | J32: =IF(Inputs!$B$49="Yes",0,IF(A32=Inputs!$B$30,H32,F32))
A33: 20 | B33: =IF(Inputs!$B$49="Yes",0,J32) | C33: =IF(Inputs!$B$49="Yes",0,IF(A33<Inputs!$B$28,Inputs!$B$26/12*B33,PMT(Inputs!$B$26/12,Inputs!$B$27*12,-B33))) | D33: =IF(Inputs!$B$49="Yes",0,B33*Inputs!$B$26/12) | E33: =IF(Inputs!$B$49="Yes",0,MAX(0,C33-D33)) | F33: =IF(Inputs!$B$49="Yes",0,MAX(0,B33-E33)) | G33: =IF(Inputs!$B$49="Yes",0,IF(A33=Inputs!$B$30,('Operating Expenses'!D17*4)/Inputs!$B$35,0)) | H33: =IF(Inputs!$B$49="Yes",0,IF(A33=Inputs!$B$30,G33*Inputs!$B$31,0)) | I33: =IF(Inputs!$B$49="Yes",0,IF(A33=Inputs!$B$30,MAX(0,H33-F33),0)) | J33: =IF(Inputs!$B$49="Yes",0,IF(A33=Inputs!$B$30,H33,F33))
A34: 21 | B34: =IF(Inputs!$B$49="Yes",0,J33) | C34: =IF(Inputs!$B$49="Yes",0,IF(A34<Inputs!$B$28,Inputs!$B$26/12*B34,PMT(Inputs!$B$26/12,Inputs!$B$27*12,-B34))) | D34: =IF(Inputs!$B$49="Yes",0,B34*Inputs!$B$26/12) | E34: =IF(Inputs!$B$49="Yes",0,MAX(0,C34-D34)) | F34: =IF(Inputs!$B$49="Yes",0,MAX(0,B34-E34)) | G34: =IF(Inputs!$B$49="Yes",0,IF(A34=Inputs!$B$30,('Operating Expenses'!D17*4)/Inputs!$B$35,0)) | H34: =IF(Inputs!$B$49="Yes",0,IF(A34=Inputs!$B$30,G34*Inputs!$B$31,0)) | I34: =IF(Inputs!$B$49="Yes",0,IF(A34=Inputs!$B$30,MAX(0,H34-F34),0)) | J34: =IF(Inputs!$B$49="Yes",0,IF(A34=Inputs!$B$30,H34,F34))
A35: 22 | B35: =IF(Inputs!$B$49="Yes",0,J34) | C35: =IF(Inputs!$B$49="Yes",0,IF(A35<Inputs!$B$28,Inputs!$B$26/12*B35,PMT(Inputs!$B$26/12,Inputs!$B$27*12,-B35))) | D35: =IF(Inputs!$B$49="Yes",0,B35*Inputs!$B$26/12) | E35: =IF(Inputs!$B$49="Yes",0,MAX(0,C35-D35)) | F35: =IF(Inputs!$B$49="Yes",0,MAX(0,B35-E35)) | G35: =IF(Inputs!$B$49="Yes",0,IF(A35=Inputs!$B$30,('Operating Expenses'!D17*4)/Inputs!$B$35,0)) | H35: =IF(Inputs!$B$49="Yes",0,IF(A35=Inputs!$B$30,G35*Inputs!$B$31,0)) | I35: =IF(Inputs!$B$49="Yes",0,IF(A35=Inputs!$B$30,MAX(0,H35-F35),0)) | J35: =IF(Inputs!$B$49="Yes",0,IF(A35=Inputs!$B$30,H35,F35))
A36: 23 | B36: =IF(Inputs!$B$49="Yes",0,J35) | C36: =IF(Inputs!$B$49="Yes",0,IF(A36<Inputs!$B$28,Inputs!$B$26/12*B36,PMT(Inputs!$B$26/12,Inputs!$B$27*12,-B36))) | D36: =IF(Inputs!$B$49="Yes",0,B36*Inputs!$B$26/12) | E36: =IF(Inputs!$B$49="Yes",0,MAX(0,C36-D36)) | F36: =IF(Inputs!$B$49="Yes",0,MAX(0,B36-E36)) | G36: =IF(Inputs!$B$49="Yes",0,IF(A36=Inputs!$B$30,('Operating Expenses'!D17*4)/Inputs!$B$35,0)) | H36: =IF(Inputs!$B$49="Yes",0,IF(A36=Inputs!$B$30,G36*Inputs!$B$31,0)) | I36: =IF(Inputs!$B$49="Yes",0,IF(A36=Inputs!$B$30,MAX(0,H36-F36),0)) | J36: =IF(Inputs!$B$49="Yes",0,IF(A36=Inputs!$B$30,H36,F36))
A37: 24 | B37: =IF(Inputs!$B$49="Yes",0,J36) | C37: =IF(Inputs!$B$49="Yes",0,IF(A37<Inputs!$B$28,Inputs!$B$26/12*B37,PMT(Inputs!$B$26/12,Inputs!$B$27*12,-B37))) | D37: =IF(Inputs!$B$49="Yes",0,B37*Inputs!$B$26/12) | E37: =IF(Inputs!$B$49="Yes",0,MAX(0,C37-D37)) | F37: =IF(Inputs!$B$49="Yes",0,MAX(0,B37-E37)) | G37: =IF(Inputs!$B$49="Yes",0,IF(A37=Inputs!$B$30,('Operating Expenses'!D17*4)/Inputs!$B$35,0)) | H37: =IF(Inputs!$B$49="Yes",0,IF(A37=Inputs!$B$30,G37*Inputs!$B$31,0)) | I37: =IF(Inputs!$B$49="Yes",0,IF(A37=Inputs!$B$30,MAX(0,H37-F37),0)) | J37: =IF(Inputs!$B$49="Yes",0,IF(A37=Inputs!$B$30,H37,F37))
A38: 25 | B38: =IF(Inputs!$B$49="Yes",0,J37) | C38: =IF(Inputs!$B$49="Yes",0,IF(A38<Inputs!$B$28,Inputs!$B$26/12*B38,PMT(Inputs!$B$26/12,Inputs!$B$27*12,-B38))) | D38: =IF(Inputs!$B$49="Yes",0,B38*Inputs!$B$26/12) | E38: =IF(Inputs!$B$49="Yes",0,MAX(0,C38-D38)) | F38: =IF(Inputs!$B$49="Yes",0,MAX(0,B38-E38)) | G38: =IF(Inputs!$B$49="Yes",0,IF(A38=Inputs!$B$30,('Operating Expenses'!D17*4)/Inputs!$B$35,0)) | H38: =IF(Inputs!$B$49="Yes",0,IF(A38=Inputs!$B$30,G38*Inputs!$B$31,0)) | I38: =IF(Inputs!$B$49="Yes",0,IF(A38=Inputs!$B$30,MAX(0,H38-F38),0)) | J38: =IF(Inputs!$B$49="Yes",0,IF(A38=Inputs!$B$30,H38,F38))
A39: 26 | B39: =IF(Inputs!$B$49="Yes",0,J38) | C39: =IF(Inputs!$B$49="Yes",0,IF(A39<Inputs!$B$28,Inputs!$B$26/12*B39,PMT(Inputs!$B$26/12,Inputs!$B$27*12,-B39))) | D39: =IF(Inputs!$B$49="Yes",0,B39*Inputs!$B$26/12) | E39: =IF(Inputs!$B$49="Yes",0,MAX(0,C39-D39)) | F39: =IF(Inputs!$B$49="Yes",0,MAX(0,B39-E39)) | G39: =IF(Inputs!$B$49="Yes",0,IF(A39=Inputs!$B$30,('Operating Expenses'!D17*4)/Inputs!$B$35,0)) | H39: =IF(Inputs!$B$49="Yes",0,IF(A39=Inputs!$B$30,G39*Inputs!$B$31,0)) | I39: =IF(Inputs!$B$49="Yes",0,IF(A39=Inputs!$B$30,MAX(0,H39-F39),0)) | J39: =IF(Inputs!$B$49="Yes",0,IF(A39=Inputs!$B$30,H39,F39))
A40: 27 | B40: =IF(Inputs!$B$49="Yes",0,J39) | C40: =IF(Inputs!$B$49="Yes",0,IF(A40<Inputs!$B$28,Inputs!$B$26/12*B40,PMT(Inputs!$B$26/12,Inputs!$B$27*12,-B40))) | D40: =IF(Inputs!$B$49="Yes",0,B40*Inputs!$B$26/12) | E40: =IF(Inputs!$B$49="Yes",0,MAX(0,C40-D40)) | F40: =IF(Inputs!$B$49="Yes",0,MAX(0,B40-E40)) | G40: =IF(Inputs!$B$49="Yes",0,IF(A40=Inputs!$B$30,('Operating Expenses'!D17*4)/Inputs!$B$35,0)) | H40: =IF(Inputs!$B$49="Yes",0,IF(A40=Inputs!$B$30,G40*Inputs!$B$31,0)) | I40: =IF(Inputs!$B$49="Yes",0,IF(A40=Inputs!$B$30,MAX(0,H40-F40),0)) | J40: =IF(Inputs!$B$49="Yes",0,IF(A40=Inputs!$B$30,H40,F40))
A41: 28 | B41: =IF(Inputs!$B$49="Yes",0,J40) | C41: =IF(Inputs!$B$49="Yes",0,IF(A41<Inputs!$B$28,Inputs!$B$26/12*B41,PMT(Inputs!$B$26/12,Inputs!$B$27*12,-B41))) | D41: =IF(Inputs!$B$49="Yes",0,B41*Inputs!$B$26/12) | E41: =IF(Inputs!$B$49="Yes",0,MAX(0,C41-D41)) | F41: =IF(Inputs!$B$49="Yes",0,MAX(0,B41-E41)) | G41: =IF(Inputs!$B$49="Yes",0,IF(A41=Inputs!$B$30,('Operating Expenses'!D17*4)/Inputs!$B$35,0)) | H41: =IF(Inputs!$B$49="Yes",0,IF(A41=Inputs!$B$30,G41*Inputs!$B$31,0)) | I41: =IF(Inputs!$B$49="Yes",0,IF(A41=Inputs!$B$30,MAX(0,H41-F41),0)) | J41: =IF(Inputs!$B$49="Yes",0,IF(A41=Inputs!$B$30,H41,F41))
A42: 29 | B42: =IF(Inputs!$B$49="Yes",0,J41) | C42: =IF(Inputs!$B$49="Yes",0,IF(A42<Inputs!$B$28,Inputs!$B$26/12*B42,PMT(Inputs!$B$26/12,Inputs!$B$27*12,-B42))) | D42: =IF(Inputs!$B$49="Yes",0,B42*Inputs!$B$26/12) | E42: =IF(Inputs!$B$49="Yes",0,MAX(0,C42-D42)) | F42: =IF(Inputs!$B$49="Yes",0,MAX(0,B42-E42)) | G42: =IF(Inputs!$B$49="Yes",0,IF(A42=Inputs!$B$30,('Operating Expenses'!D17*4)/Inputs!$B$35,0)) | H42: =IF(Inputs!$B$49="Yes",0,IF(A42=Inputs!$B$30,G42*Inputs!$B$31,0)) | I42: =IF(Inputs!$B$49="Yes",0,IF(A42=Inputs!$B$30,MAX(0,H42-F42),0)) | J42: =IF(Inputs!$B$49="Yes",0,IF(A42=Inputs!$B$30,H42,F42))
A43: 30 | B43: =IF(Inputs!$B$49="Yes",0,J42) | C43: =IF(Inputs!$B$49="Yes",0,IF(A43<Inputs!$B$28,Inputs!$B$26/12*B43,PMT(Inputs!$B$26/12,Inputs!$B$27*12,-B43))) | D43: =IF(Inputs!$B$49="Yes",0,B43*Inputs!$B$26/12) | E43: =IF(Inputs!$B$49="Yes",0,MAX(0,C43-D43)) | F43: =IF(Inputs!$B$49="Yes",0,MAX(0,B43-E43)) | G43: =IF(Inputs!$B$49="Yes",0,IF(A43=Inputs!$B$30,('Operating Expenses'!D17*4)/Inputs!$B$35,0)) | H43: =IF(Inputs!$B$49="Yes",0,IF(A43=Inputs!$B$30,G43*Inputs!$B$31,0)) | I43: =IF(Inputs!$B$49="Yes",0,IF(A43=Inputs!$B$30,MAX(0,H43-F43),0)) | J43: =IF(Inputs!$B$49="Yes",0,IF(A43=Inputs!$B$30,H43,F43))
...

Sheet Fees
A1: Sponsor Fee Module
A3: Year | B3: EGI | C3: Acquisition Fee | D3: Asset Management Fee | E3: Disposition Fee | F3: Total Sponsor Fees
A4: 0 | B4: 0 | C4: =Inputs!B4*Inputs!B7 | D4: 0 | E4: 0 | F4: =SUM(C4:E4)
A5: 1 | B5: ='Revenue Forecast'!F4 | C5: 0 | D5: =B5*Inputs!$B$8 | E5: =IF(A5=Inputs!$B$35/12,'Returns Summary'!B15*Inputs!$B$9,0) | F5: =SUM(C5:E5)
A6: 2 | B6: ='Revenue Forecast'!F5 | C6: 0 | D6: =B6*Inputs!$B$8 | E6: =IF(A6=Inputs!$B$35/12,'Returns Summary'!B15*Inputs!$B$9,0) | F6: =SUM(C6:E6)
A7: 3 | B7: ='Revenue Forecast'!F6 | C7: 0 | D7: =B7*Inputs!$B$8 | E7: =IF(A7=Inputs!$B$35/12,'Returns Summary'!B15*Inputs!$B$9,0) | F7: =SUM(C7:E7)
A8: 4 | B8: ='Revenue Forecast'!F7 | C8: 0 | D8: =B8*Inputs!$B$8 | E8: =IF(A8=Inputs!$B$35/12,'Returns Summary'!B15*Inputs!$B$9,0) | F8: =SUM(C8:E8)
A9: 5 | B9: ='Revenue Forecast'!F8 | C9: 0 | D9: =B9*Inputs!$B$8 | E9: =IF(A9=Inputs!$B$35/12,'Returns Summary'!B15*Inputs!$B$9,0) | F9: =SUM(C9:E9)

Sheet GP-LP Waterfall
A1: GP / LP Waterfall with Promote - Tiered Structure
A3: Equity Contributions
A4: Total Equity Required | B4: ='Returns Summary'!B14
A5: GP Co-Invest | B5: =B4*Inputs!B10
A6: LP Equity | B6: =B4-B5
A9: Year | B9: Distributable CF | C9: Return of Capital 100% LP | D9: Preferred Return 8% | E9: Remaining CF | F9: Catch-Up LP 80% | G9: Catch-Up GP 20% | H9: Residual LP 80% | I9: Residual GP 20% | J9: LP Total | K9: GP Total
A10: 1 | B10: ='Returns Summary'!I6 | C10: =MIN(B10,MAX(0,$B$6-0)) | D10: =MIN(MAX(0,B10-C10),$B$6*Inputs!$B$44) | E10: =MAX(0,B10-C10-D10) | F10: =MIN(E10,$B$6*Inputs!$B$44)*Inputs!$B$42 | G10: =MIN(E10,$B$6*Inputs!$B$44)*Inputs!$B$43 | H10: =MAX(0,E10-F10-G10)*Inputs!$B$45 | I10: =MAX(0,E10-F10-G10)*Inputs!$B$46 | J10: =C10+D10+F10+H10 | K10: =G10+I10
A11: 2 | B11: ='Returns Summary'!I7 | C11: =MIN(B11,MAX(0,$B$6-SUM($C$10:C10))) | D11: =MIN(MAX(0,B11-C11),$B$6*Inputs!$B$44) | E11: =MAX(0,B11-C11-D11) | F11: =MIN(E11,$B$6*Inputs!$B$44)*Inputs!$B$42 | G11: =MIN(E11,$B$6*Inputs!$B$44)*Inputs!$B$43 | H11: =MAX(0,E11-F11-G11)*Inputs!$B$45 | I11: =MAX(0,E11-F11-G11)*Inputs!$B$46 | J11: =C11+D11+F11+H11 | K11: =G11+I11
A12: 3 | B12: ='Returns Summary'!I8 | C12: =MIN(B12,MAX(0,$B$6-SUM($C$10:C11))) | D12: =MIN(MAX(0,B12-C12),$B$6*Inputs!$B$44) | E12: =MAX(0,B12-C12-D12) | F12: =MIN(E12,$B$6*Inputs!$B$44)*Inputs!$B$42 | G12: =MIN(E12,$B$6*Inputs!$B$44)*Inputs!$B$43 | H12: =MAX(0,E12-F12-G12)*Inputs!$B$45 | I12: =MAX(0,E12-F12-G12)*Inputs!$B$46 | J12: =C12+D12+F12+H12 | K12: =G12+I12
A13: 4 | B13: ='Returns Summary'!I9 | C13: =MIN(B13,MAX(0,$B$6-SUM($C$10:C12))) | D13: =MIN(MAX(0,B13-C13),$B$6*Inputs!$B$44) | E13: =MAX(0,B13-C13-D13) | F13: =MIN(E13,$B$6*Inputs!$B$44)*Inputs!$B$42 | G13: =MIN(E13,$B$6*Inputs!$B$44)*Inputs!$B$43 | H13: =MAX(0,E13-F13-G13)*Inputs!$B$45 | I13: =MAX(0,E13-F13-G13)*Inputs!$B$46 | J13: =C13+D13+F13+H13 | K13: =G13+I13
A14: 5 | B14: ='Returns Summary'!I10 | C14: =MIN(B14,MAX(0,$B$6-SUM($C$10:C13))) | D14: =MIN(MAX(0,B14-C14),$B$6*Inputs!$B$44) | E14: =MAX(0,B14-C14-D14) | F14: =MIN(E14,$B$6*Inputs!$B$44)*Inputs!$B$42 | G14: =MIN(E14,$B$6*Inputs!$B$44)*Inputs!$B$43 | H14: =MAX(0,E14-F14-G14)*Inputs!$B$45 | I14: =MAX(0,E14-F14-G14)*Inputs!$B$46 | J14: =C14+D14+F14+H14 | K14: =G14+I14
A17: Waterfall Summary
A18: LP Total Distributions | B18: =SUM(J10:J14) | D18: LP CF | E18: GP CF
A19: GP Total Distributions | B19: =SUM(K10:K14) | D19: =-$B$6 | E19: =-$B$5
A20: LP Equity Multiple | B20: =IFERROR(B18/B6,"N/A") | D20: =J10 | E20: =K10
A21: GP Equity Multiple | B21: =IFERROR(B19/B5,"N/A") | D21: =J11 | E21: =K11
A22: LP IRR | B22: =IFERROR(IRR(D19:D24),"N/A") | D22: =J12 | E22: =K12
A23: GP IRR | B23: =IFERROR(IRR(E19:E24),"N/A") | D23: =J13 | E23: =K13
A24: Total MOIC | B24: =IFERROR((B18+B19)/B4,"N/A") | D24: =J14 | E24: =K14

Sheet Returns Summary
A1: Returns Summary / Cash Flow Model
A4: Year | B4: NOI | C4: Expansion NOI | D4: Debt Service | E4: Refi Proceeds | F4: Sponsor Fees | G4: Net Cash Flow Before Sale | H4: Sale Proceeds | I4: Total Cash Flow
A5: 0 | I5: =-'Debt & Refi'!B6
A6: 1 | B6: ='Operating Expenses'!B17 | C6: =SUM('Expansion CapEx'!F17:F28) | D6: =SUM('Debt & Refi'!C14:C25) | E6: =SUM('Debt & Refi'!I14:I25) | F6: =Fees!F5 | G6: =B6+C6-D6+E6-F6 | H6: =IF(A6=Inputs!$B$36/12,MAX(0,B6/Inputs!$B$35*(1-Inputs!$B$37)-'Debt & Refi'!J73),0) | I6: =G6+H6
A7: 2 | B7: ='Operating Expenses'!C17 | C7: =SUM('Expansion CapEx'!F29:F40) | D7: =SUM('Debt & Refi'!C26:C37) | E7: =SUM('Debt & Refi'!I26:I37) | F7: =Fees!F6 | G7: =B7+C7-D7+E7-F7 | H7: =IF(A7=Inputs!$B$36/12,MAX(0,B7/Inputs!$B$35*(1-Inputs!$B$37)-'Debt & Refi'!J73),0) | I7: =G7+H7
A8: 3 | B8: ='Operating Expenses'!D17 | C8: =SUM('Expansion CapEx'!F41:F52) | D8: =SUM('Debt & Refi'!C38:C49) | E8: =SUM('Debt & Refi'!I38:I49) | F8: =Fees!F7 | G8: =B8+C8-D8+E8-F8 | H8: =IF(A8=Inputs!$B$36/12,MAX(0,B8/Inputs!$B$35*(1-Inputs!$B$37)-'Debt & Refi'!J73),0) | I8: =G8+H8
A9: 4 | B9: ='Operating Expenses'!E17 | C9: =SUM('Expansion CapEx'!F53:F64) | D9: =SUM('Debt & Refi'!C50:C61) | E9: =SUM('Debt & Refi'!I50:I61) | F9: =Fees!F8 | G9: =B9+C9-D9+E9-F9 | H9: =IF(A9=Inputs!$B$36/12,MAX(0,B9/Inputs!$B$35*(1-Inputs!$B$37)-'Debt & Refi'!J73),0) | I9: =G9+H9
A10: 5 | B10: ='Operating Expenses'!F17 | C10: =SUM('Expansion CapEx'!F65:F76) | D10: =SUM('Debt & Refi'!C62:C73) | E10: =SUM('Debt & Refi'!I62:I73) | F10: =Fees!F9 | G10: =B10+C10-D10+E10-F10 | H10: =IF(A10=Inputs!$B$36/12,MAX(0,B10/Inputs!$B$35*(1-Inputs!$B$37)-'Debt & Refi'!J73),0) | I10: =G10+H10
A13: Return Metrics
A14: Total Equity | B14: =-I5
A15: Exit Value | B15: =B10/Inputs!B35
A16: Levered IRR | B16: =IRR(I5:I10)
A17: Equity Multiple | B17: =SUM(I6:I10)/ABS(I5)
A18: Avg Cash-on-Cash | B18: =AVERAGE(G6:G10)/ABS(I5)
A19: Year 1 DSCR | B19: =IF(Inputs!$B$49="Yes","N/A",IFERROR('Operating Expenses'!B17/'Debt & Refi'!B7,"N/A"))
A20: Year 1 Debt Yield | B20: =IF(Inputs!$B$49="Yes","N/A",IFERROR('Operating Expenses'!B17/'Debt & Refi'!B5,"N/A"))
A22: Unlevered Metrics
A23: Unlevered IRR | B23: ='Unlevered Scenarios'!B22
A24: Unlevered Equity Multiple | B24: ='Unlevered Scenarios'!B23
A25: Unlevered Avg Cash-on-Cash | B25: ='Unlevered Scenarios'!B24
A26: Unlevered Exit Value | B26: ='Unlevered Scenarios'!B25
A27: Unlevered Net Sale Proceeds | B27: ='Unlevered Scenarios'!B26
A28: Unlevered Y5 NOI Yield on Cost | B28: ='Unlevered Scenarios'!B27
A29: Active Scenario | B29: Base / Current
A31: Expanded Return Metrics
A32: LP Equity Multiple | B32: ='GP-LP Waterfall'!B20
A33: GP Equity Multiple | B33: ='GP-LP Waterfall'!B21
A34: MOIC | B34: =B17
A35: Yield on Cost | B35: =B10/'Debt & Refi'!B4
A36: Exit Yield | B36: =B10/B15
A38: Acquisition Diagnostics
A39: Price per Rentable SF | B39: =IFERROR(Inputs!B4/('Unit Mix & Market Comps'!B11*'Unit Mix & Market Comps'!C11),"N/A")
A40: Price per Unit | B40: =IFERROR(Inputs!B4/'Unit Mix & Market Comps'!B11,"N/A")
A41: Going-In Cap | B41: =IFERROR('Operating Expenses'!B17/Inputs!B4,"N/A")
A42: Stabilized Cap | B42: =IFERROR('Operating Expenses'!F17/Inputs!B4,"N/A")
A43: Total Cost per Rentable SF | B43: =IFERROR('Debt & Refi'!B4/('Unit Mix & Market Comps'!B11*'Unit Mix & Market Comps'!C11),"N/A")
A44: Total Cost per Unit | B44: =IFERROR('Debt & Refi'!B4/'Unit Mix & Market Comps'!B11,"N/A")
A46: Debt Mode | B46: =Inputs!B50
A47: Unlevered Toggle | B47: =Inputs!B49

Sheet Sensitivity
A1: Sensitivity Tables
A3: Purchase Price / Exit Cap Sensitivity - Approx Levered IRR
A4: Exit Cap / Price | B4: 8000000 | C4: 9000000 | D4: 10000000 | E4: 11000000 | F4: 12000000
A5: 0.065 | B5: =((('Operating Expenses'!F17/B$4)*(1-$A5)+0.01)*5) | C5: =((('Operating Expenses'!F17/C$4)*(1-$A5)+0.01)*5) | D5: =((('Operating Expenses'!F17/D$4)*(1-$A5)+0.01)*5) | E5: =((('Operating Expenses'!F17/E$4)*(1-$A5)+0.01)*5) | F5: =((('Operating Expenses'!F17/F$4)*(1-$A5)+0.01)*5)
A6: 0.07 | B6: =((('Operating Expenses'!F17/B$4)*(1-$A6)+0.01)*5) | C6: =((('Operating Expenses'!F17/C$4)*(1-$A6)+0.01)*5) | D6: =((('Operating Expenses'!F17/D$4)*(1-$A6)+0.01)*5) | E6: =((('Operating Expenses'!F17/E$4)*(1-$A6)+0.01)*5) | F6: =((('Operating Expenses'!F17/F$4)*(1-$A6)+0.01)*5)
A7: 0.0725 | B7: =((('Operating Expenses'!F17/B$4)*(1-$A7)+0.01)*5) | C7: =((('Operating Expenses'!F17/C$4)*(1-$A7)+0.01)*5) | D7: =((('Operating Expenses'!F17/D$4)*(1-$A7)+0.01)*5) | E7: =((('Operating Expenses'!F17/E$4)*(1-$A7)+0.01)*5) | F7: =((('Operating Expenses'!F17/F$4)*(1-$A7)+0.01)*5)
A8: 0.075 | B8: =((('Operating Expenses'!F17/B$4)*(1-$A8)+0.01)*5) | C8: =((('Operating Expenses'!F17/C$4)*(1-$A8)+0.01)*5) | D8: =((('Operating Expenses'!F17/D$4)*(1-$A8)+0.01)*5) | E8: =((('Operating Expenses'!F17/E$4)*(1-$A8)+0.01)*5) | F8: =((('Operating Expenses'!F17/F$4)*(1-$A8)+0.01)*5)
A9: 0.08 | B9: =((('Operating Expenses'!F17/B$4)*(1-$A9)+0.01)*5) | C9: =((('Operating Expenses'!F17/C$4)*(1-$A9)+0.01)*5) | D9: =((('Operating Expenses'!F17/D$4)*(1-$A9)+0.01)*5) | E9: =((('Operating Expenses'!F17/E$4)*(1-$A9)+0.01)*5) | F9: =((('Operating Expenses'!F17/F$4)*(1-$A9)+0.01)*5)
A13: Occupancy / Rent Growth Sensitivity - Year 5 NOI
A14: Rent Growth / Occ | B14: 0.82 | C14: 0.86 | D14: 0.9 | E14: 0.92 | F14: 0.94
A15: 0.02 | B15: =('Unit Mix & Market Comps'!$H$11*(1+$A15)^5*B$14*(1-Inputs!$B$17)+Inputs!$B$21*12)-'Operating Expenses'!F15 | C15: =('Unit Mix & Market Comps'!$H$11*(1+$A15)^5*C$14*(1-Inputs!$B$17)+Inputs!$B$21*12)-'Operating Expenses'!F15 | D15: =('Unit Mix & Market Comps'!$H$11*(1+$A15)^5*D$14*(1-Inputs!$B$17)+Inputs!$B$21*12)-'Operating Expenses'!F15 | E15: =('Unit Mix & Market Comps'!$H$11*(1+$A15)^5*E$14*(1-Inputs!$B$17)+Inputs!$B$21*12)-'Operating Expenses'!F15 | F15: =('Unit Mix & Market Comps'!$H$11*(1+$A15)^5*F$14*(1-Inputs!$B$17)+Inputs!$B$21*12)-'Operating Expenses'!F15
A16: 0.03 | B16: =('Unit Mix & Market Comps'!$H$11*(1+$A16)^5*B$14*(1-Inputs!$B$17)+Inputs!$B$21*12)-'Operating Expenses'!F15 | C16: =('Unit Mix & Market Comps'!$H$11*(1+$A16)^5*C$14*(1-Inputs!$B$17)+Inputs!$B$21*12)-'Operating Expenses'!F15 | D16: =('Unit Mix & Market Comps'!$H$11*(1+$A16)^5*D$14*(1-Inputs!$B$17)+Inputs!$B$21*12)-'Operating Expenses'!F15 | E16: =('Unit Mix & Market Comps'!$H$11*(1+$A16)^5*E$14*(1-Inputs!$B$17)+Inputs!$B$21*12)-'Operating Expenses'!F15 | F16: =('Unit Mix & Market Comps'!$H$11*(1+$A16)^5*F$14*(1-Inputs!$B$17)+Inputs!$B$21*12)-'Operating Expenses'!F15
A17: 0.04 | B17: =('Unit Mix & Market Comps'!$H$11*(1+$A17)^5*B$14*(1-Inputs!$B$17)+Inputs!$B$21*12)-'Operating Expenses'!F15 | C17: =('Unit Mix & Market Comps'!$H$11*(1+$A17)^5*C$14*(1-Inputs!$B$17)+Inputs!$B$21*12)-'Operating Expenses'!F15 | D17: =('Unit Mix & Market Comps'!$H$11*(1+$A17)^5*D$14*(1-Inputs!$B$17)+Inputs!$B$21*12)-'Operating Expenses'!F15 | E17: =('Unit Mix & Market Comps'!$H$11*(1+$A17)^5*E$14*(1-Inputs!$B$17)+Inputs!$B$21*12)-'Operating Expenses'!F15 | F17: =('Unit Mix & Market Comps'!$H$11*(1+$A17)^5*F$14*(1-Inputs!$B$17)+Inputs!$B$21*12)-'Operating Expenses'!F15
A18: 0.05 | B18: =('Unit Mix & Market Comps'!$H$11*(1+$A18)^5*B$14*(1-Inputs!$B$17)+Inputs!$B$21*12)-'Operating Expenses'!F15 | C18: =('Unit Mix & Market Comps'!$H$11*(1+$A18)^5*C$14*(1-Inputs!$B$17)+Inputs!$B$21*12)-'Operating Expenses'!F15 | D18: =('Unit Mix & Market Comps'!$H$11*(1+$A18)^5*D$14*(1-Inputs!$B$17)+Inputs!$B$21*12)-'Operating Expenses'!F15 | E18: =('Unit Mix & Market Comps'!$H$11*(1+$A18)^5*E$14*(1-Inputs!$B$17)+Inputs!$B$21*12)-'Operating Expenses'!F15 | F18: =('Unit Mix & Market Comps'!$H$11*(1+$A18)^5*F$14*(1-Inputs!$B$17)+Inputs!$B$21*12)-'Operating Expenses'!F15
A19: 0.06 | B19: =('Unit Mix & Market Comps'!$H$11*(1+$A19)^5*B$14*(1-Inputs!$B$17)+Inputs!$B$21*12)-'Operating Expenses'!F15 | C19: =('Unit Mix & Market Comps'!$H$11*(1+$A19)^5*C$14*(1-Inputs!$B$17)+Inputs!$B$21*12)-'Operating Expenses'!F15 | D19: =('Unit Mix & Market Comps'!$H$11*(1+$A19)^5*D$14*(1-Inputs!$B$17)+Inputs!$B$21*12)-'Operating Expenses'!F15 | E19: =('Unit Mix & Market Comps'!$H$11*(1+$A19)^5*E$14*(1-Inputs!$B$17)+Inputs!$B$21*12)-'Operating Expenses'!F15 | F19: =('Unit Mix & Market Comps'!$H$11*(1+$A19)^5*F$14*(1-Inputs!$B$17)+Inputs!$B$21*12)-'Operating Expenses'!F15

Sheet Unlevered Scenarios
A1: Unlevered Scenario Analysis
A3: Scenario Assumptions
A4: Purchase Price | B4: =Inputs!B4 | C4: =10500000 | D4: =9500000 | E4: =10000000 | F4: =10000000
A5: Closing Costs % | B5: =Inputs!B5 | C5: =0.02 | D5: =0.02 | E5: =0.02 | F5: =0.02
A6: Initial Repairs / Deferred CapEx | B6: =Inputs!B6 | C6: =250000 | D6: =250000 | E6: =250000 | F6: =250000
A7: Acquisition Fee % | B7: =Inputs!B7 | C7: =0.02 | D7: =0.02 | E7: =0.02 | F7: =0.02
A8: Exit Cap Rate | B8: =Inputs!B35 | C8: =0.0775 | D8: =0.0674999999999999 | E8: =0.0624999999999999 | F8: =0.0824999999999999
A9: Selling Costs % | B9: =Inputs!B37 | C9: =0.02 | D9: =0.02 | E9: =0.02 | F9: =0.02
A10: Total Unlevered Cost | B10: =B4*(1+B5)+B6 | C10: =11170000 | D10: =10130000 | E10: =10650000 | F10: =10650000
A12: Annual Unlevered Cash Flow
A13: Year | B13: Base / Current | C13: Downside | D13: Upside | E13: Lower Exit Cap | F13: Higher Exit Cap
A14: 0 | B14: =-B10 | C14: =-11170000 | D14: =-10130000 | E14: =-10650000 | F14: =-10650000
A15: 1 | B15: ='Operating Expenses'!B17 | C15: =489943.81836461 | D15: =543208.227090963 | E15: =516576.022727787 | F15: =516576.022727787
A16: 2 | B16: ='Operating Expenses'!C17 | C16: =661628.890265463 | D16: =733276.938775935 | E16: =697452.914520699 | F16: =697452.914520699
A17: 3 | B17: ='Operating Expenses'!D17 | C17: =911821.49798933 | D17: =1001417.90123847 | E17: =956619.699613901 | F17: =956619.699613901
A18: 4 | B18: ='Operating Expenses'!E17 | C18: =1186335.28161739 | D18: =1294875.90603635 | E18: =1240605.59382687 | F18: =1240605.59382687
A19: 5 | B19: ='Operating Expenses'!F17+('Operating Expenses'!F17/B8*(1-B9)) | C19: =14753781.8391852 | D19: =18505915.4386592 | E19: =18940145.6821185 | F19: =14659047.3007037
A21: Unlevered Return Metrics
A22: Unlevered IRR | B22: =IFERROR(IRR(B14:B19),"N/A")
A23: Equity Multiple | B23: =IFERROR(SUM(B15:B19)/ABS(B14),"N/A") | C23: =1.61177361928576 | D23: =2.17953547994087 | E23: =2.09872299650778 | F23: =1.69674192783032
A24: Avg Cash-on-Cash | B24: =IFERROR(AVERAGE(B15:B18)/ABS(B14),"N/A") | C24: =0.0727334263258012 | D24: =0.0881732224368639 | E24: =0.0800763903917667 | F24: =0.0800763903917667
A25: Exit Value | B25: ='Operating Expenses'!F17/B8 | C25: =13805591.0814429 | D25: =17519375.8168019 | E25: =18019929.4115677 | F25: =13651461.67543
A26: Net Sale Proceeds | B26: ='Operating Expenses'!F17/B8*(1-B9) | C26: =13529479.2598141 | D26: =17168988.3004659 | E26: =17659530.8233363 | F26: =13378432.4419214
A27: Year 5 NOI Yield on Cost | B27: ='Operating Expenses'!F17/B10 | C27: =0.0957863302427781 | D27: =0.116738190289647 | E27: =0.105750759457556 | F27: =0.105750759457556
A28: Notes | B28: All scenarios are debt-free and exclude refi proceeds/debt service. Downside/Upside flex Year 1-5 NOI by +/-5% and sale value accordingly.
A32: UNLEVERED IRR SCENARIO ANALYSIS
A34: Scenario | B34: Exit Cap Rate | C34: NOI Growth | D34: Hold Period | E34: Projected Unlevered IRR
A35: Severe Downside | B35: 8.00% | C35: 1.0% | D35: 5 Years | E35: 5.0% - 6.5%
A36: Downside | B36: 7.50% | C36: 2.0% | D36: 5 Years | E36: 6.5% - 8.0%
A37: Base Case | B37: 6.75% | C37: 3.0% | D37: 5 Years | E37: 9.0% - 11.0%
A38: Strong Upside | B38: 6.00% | C38: 4.0% | D38: 5 Years | E38: 12.0% - 15.0%
A39: Aggressive Upside | B39: 5.50% | C39: 5.0% | D39: 7 Years | E39: 16.0% - 20.0%
A40: Expansion / Redevelopment | B40: 5.00% | C40: 6.0% | D40: 7-10 Years | E40: 20.0%+
A42: Acquisition Diagnostics
A43: Price per Rentable SF | B43: ='Returns Summary'!B39
A44: Price per Unit | B44: ='Returns Summary'!B40
A45: Going-In Cap | B45: ='Returns Summary'!B41
A46: Stabilized Cap | B46: ='Returns Summary'!B42
A47: Yield on Cost | B47: ='Returns Summary'!B35
A48: Exit Yield | B48: ='Returns Summary'!B36
...
